[2023-11-09T11:44:09.587+0000] {taskinstance.py:1157} INFO - Dependencies all met for dep_context=non-requeueable deps ti=<TaskInstance: covid_data_dag_mongo.print_vaccinations_operator manual__2023-11-09T11:42:32.691448+00:00 [queued]>
[2023-11-09T11:44:09.608+0000] {taskinstance.py:1157} INFO - Dependencies all met for dep_context=requeueable deps ti=<TaskInstance: covid_data_dag_mongo.print_vaccinations_operator manual__2023-11-09T11:42:32.691448+00:00 [queued]>
[2023-11-09T11:44:09.609+0000] {taskinstance.py:1359} INFO - Starting attempt 1 of 2
[2023-11-09T11:44:10.308+0000] {taskinstance.py:1380} INFO - Executing <Task(PythonOperator): print_vaccinations_operator> on 2023-11-09 11:42:32.691448+00:00
[2023-11-09T11:44:10.318+0000] {standard_task_runner.py:57} INFO - Started process 1997 to run task
[2023-11-09T11:44:10.325+0000] {standard_task_runner.py:84} INFO - Running: ['***', 'tasks', 'run', 'covid_data_dag_mongo', 'print_vaccinations_operator', 'manual__2023-11-09T11:42:32.691448+00:00', '--job-id', '721', '--raw', '--subdir', 'DAGS_FOLDER/Dag_mongo.py', '--cfg-path', '/tmp/tmpei4dhhn8']
[2023-11-09T11:44:10.332+0000] {standard_task_runner.py:85} INFO - Job 721: Subtask print_vaccinations_operator
[2023-11-09T11:44:10.406+0000] {task_command.py:415} INFO - Running <TaskInstance: covid_data_dag_mongo.print_vaccinations_operator manual__2023-11-09T11:42:32.691448+00:00 [running]> on host 172.21.0.7
[2023-11-09T11:44:10.508+0000] {taskinstance.py:1660} INFO - Exporting env vars: AIRFLOW_CTX_DAG_OWNER='***' AIRFLOW_CTX_DAG_ID='covid_data_dag_mongo' AIRFLOW_CTX_TASK_ID='print_vaccinations_operator' AIRFLOW_CTX_EXECUTION_DATE='2023-11-09T11:42:32.691448+00:00' AIRFLOW_CTX_TRY_NUMBER='1' AIRFLOW_CTX_DAG_RUN_ID='manual__2023-11-09T11:42:32.691448+00:00'
[2023-11-09T11:44:10.531+0000] {taskinstance.py:1935} ERROR - Task failed with exception
Traceback (most recent call last):
  File "/home/airflow/.local/lib/python3.8/site-packages/airflow/operators/python.py", line 192, in execute
    return_value = self.execute_callable()
  File "/home/airflow/.local/lib/python3.8/site-packages/airflow/operators/python.py", line 209, in execute_callable
    return self.python_callable(*self.op_args, **self.op_kwargs)
  File "/opt/airflow/dags/Dag_mongo.py", line 131, in print_vaccinations
    hook = MongoHook(conn_id="mongo_default")
  File "/home/airflow/.local/lib/python3.8/site-packages/airflow/providers/mongo/hooks/mongo.py", line 63, in __init__
    self.connection = self.get_connection(conn_id)
  File "/home/airflow/.local/lib/python3.8/site-packages/airflow/hooks/base.py", line 72, in get_connection
    conn = Connection.get_connection_from_secrets(conn_id)
  File "/home/airflow/.local/lib/python3.8/site-packages/airflow/models/connection.py", line 477, in get_connection_from_secrets
    raise AirflowNotFoundException(f"The conn_id `{conn_id}` isn't defined")
airflow.exceptions.AirflowNotFoundException: The conn_id `mongo_default` isn't defined
[2023-11-09T11:44:10.543+0000] {taskinstance.py:1398} INFO - Marking task as UP_FOR_RETRY. dag_id=covid_data_dag_mongo, task_id=print_vaccinations_operator, execution_date=20231109T114232, start_date=20231109T114409, end_date=20231109T114410
[2023-11-09T11:44:10.561+0000] {standard_task_runner.py:104} ERROR - Failed to execute job 721 for task print_vaccinations_operator (The conn_id `mongo_default` isn't defined; 1997)
[2023-11-09T11:44:10.578+0000] {local_task_job_runner.py:228} INFO - Task exited with return code 1
[2023-11-09T11:44:10.601+0000] {taskinstance.py:2776} INFO - 0 downstream tasks scheduled from follow-on schedule check
