[2023-11-14T08:11:23.774+0000] {taskinstance.py:1157} INFO - Dependencies all met for dep_context=non-requeueable deps ti=<TaskInstance: covid_data_dag_postgres.wrangle_cases_deaths manual__2023-11-14T08:10:58.716882+00:00 [queued]>
[2023-11-14T08:11:23.878+0000] {taskinstance.py:1157} INFO - Dependencies all met for dep_context=requeueable deps ti=<TaskInstance: covid_data_dag_postgres.wrangle_cases_deaths manual__2023-11-14T08:10:58.716882+00:00 [queued]>
[2023-11-14T08:11:23.896+0000] {taskinstance.py:1359} INFO - Starting attempt 1 of 2
[2023-11-14T08:11:24.183+0000] {taskinstance.py:1380} INFO - Executing <Task(PythonOperator): wrangle_cases_deaths> on 2023-11-14 08:10:58.716882+00:00
[2023-11-14T08:11:24.237+0000] {standard_task_runner.py:57} INFO - Started process 619 to run task
[2023-11-14T08:11:24.294+0000] {standard_task_runner.py:84} INFO - Running: ['***', 'tasks', 'run', 'covid_data_dag_postgres', 'wrangle_cases_deaths', 'manual__2023-11-14T08:10:58.716882+00:00', '--job-id', '894', '--raw', '--subdir', 'DAGS_FOLDER/Dag_postgres.py', '--cfg-path', '/tmp/tmpxnw_qoq2']
[2023-11-14T08:11:24.420+0000] {standard_task_runner.py:85} INFO - Job 894: Subtask wrangle_cases_deaths
[2023-11-14T08:11:26.833+0000] {task_command.py:415} INFO - Running <TaskInstance: covid_data_dag_postgres.wrangle_cases_deaths manual__2023-11-14T08:10:58.716882+00:00 [running]> on host 172.21.0.4
[2023-11-14T08:11:27.228+0000] {taskinstance.py:1660} INFO - Exporting env vars: AIRFLOW_CTX_DAG_OWNER='***' AIRFLOW_CTX_DAG_ID='covid_data_dag_postgres' AIRFLOW_CTX_TASK_ID='wrangle_cases_deaths' AIRFLOW_CTX_EXECUTION_DATE='2023-11-14T08:10:58.716882+00:00' AIRFLOW_CTX_TRY_NUMBER='1' AIRFLOW_CTX_DAG_RUN_ID='manual__2023-11-14T08:10:58.716882+00:00'
[2023-11-14T08:11:29.066+0000] {logging_mixin.py:151} INFO - Formatting date…
[2023-11-14T08:11:29.391+0000] {logging_mixin.py:151} INFO - Discarding rows…
[2023-11-14T08:11:29.466+0000] {taskinstance.py:1935} ERROR - Task failed with exception
Traceback (most recent call last):
  File "/home/airflow/.local/lib/python3.8/site-packages/airflow/operators/python.py", line 192, in execute
    return_value = self.execute_callable()
  File "/home/airflow/.local/lib/python3.8/site-packages/airflow/operators/python.py", line 209, in execute_callable
    return self.python_callable(*self.op_args, **self.op_kwargs)
  File "/opt/airflow/dags/Dag_postgres.py", line 125, in wrangle_cases_deaths
    df = _inject_growth(df, 'weekly', 7)
  File "/opt/airflow/dags/Dag_postgres.py", line 84, in _inject_growth
    df[["country", "New_cases", "New_deaths"]]
  File "/home/airflow/.local/lib/python3.8/site-packages/pandas/core/frame.py", line 3767, in __getitem__
    indexer = self.columns._get_indexer_strict(key, "columns")[1]
  File "/home/airflow/.local/lib/python3.8/site-packages/pandas/core/indexes/base.py", line 5877, in _get_indexer_strict
    self._raise_if_missing(keyarr, indexer, axis_name)
  File "/home/airflow/.local/lib/python3.8/site-packages/pandas/core/indexes/base.py", line 5941, in _raise_if_missing
    raise KeyError(f"{not_found} not in index")
KeyError: "['country'] not in index"
[2023-11-14T08:11:29.577+0000] {taskinstance.py:1398} INFO - Marking task as UP_FOR_RETRY. dag_id=covid_data_dag_postgres, task_id=wrangle_cases_deaths, execution_date=20231114T081058, start_date=20231114T081123, end_date=20231114T081129
[2023-11-14T08:11:29.675+0000] {standard_task_runner.py:104} ERROR - Failed to execute job 894 for task wrangle_cases_deaths ("['country'] not in index"; 619)
[2023-11-14T08:11:29.771+0000] {local_task_job_runner.py:228} INFO - Task exited with return code 1
[2023-11-14T08:11:30.442+0000] {taskinstance.py:2776} INFO - 0 downstream tasks scheduled from follow-on schedule check
