[2023-11-13T16:45:40.879+0000] {taskinstance.py:1157} INFO - Dependencies all met for dep_context=non-requeueable deps ti=<TaskInstance: covid_data_dag_postgres.wrangle_population_data manual__2023-11-13T16:43:41.031437+00:00 [queued]>
[2023-11-13T16:45:41.077+0000] {taskinstance.py:1157} INFO - Dependencies all met for dep_context=requeueable deps ti=<TaskInstance: covid_data_dag_postgres.wrangle_population_data manual__2023-11-13T16:43:41.031437+00:00 [queued]>
[2023-11-13T16:45:41.079+0000] {taskinstance.py:1359} INFO - Starting attempt 2 of 2
[2023-11-13T16:45:41.300+0000] {taskinstance.py:1380} INFO - Executing <Task(PythonOperator): wrangle_population_data> on 2023-11-13 16:43:41.031437+00:00
[2023-11-13T16:45:41.388+0000] {standard_task_runner.py:57} INFO - Started process 476 to run task
[2023-11-13T16:45:41.428+0000] {standard_task_runner.py:84} INFO - Running: ['***', 'tasks', 'run', 'covid_data_dag_postgres', 'wrangle_population_data', 'manual__2023-11-13T16:43:41.031437+00:00', '--job-id', '818', '--raw', '--subdir', 'DAGS_FOLDER/Dag_postgres.py', '--cfg-path', '/tmp/tmpug4b24l_']
[2023-11-13T16:45:41.470+0000] {standard_task_runner.py:85} INFO - Job 818: Subtask wrangle_population_data
[2023-11-13T16:45:43.928+0000] {task_command.py:415} INFO - Running <TaskInstance: covid_data_dag_postgres.wrangle_population_data manual__2023-11-13T16:43:41.031437+00:00 [running]> on host 172.21.0.9
[2023-11-13T16:45:44.429+0000] {taskinstance.py:1660} INFO - Exporting env vars: AIRFLOW_CTX_DAG_OWNER='***' AIRFLOW_CTX_DAG_ID='covid_data_dag_postgres' AIRFLOW_CTX_TASK_ID='wrangle_population_data' AIRFLOW_CTX_EXECUTION_DATE='2023-11-13T16:43:41.031437+00:00' AIRFLOW_CTX_TRY_NUMBER='2' AIRFLOW_CTX_DAG_RUN_ID='manual__2023-11-13T16:43:41.031437+00:00'
[2023-11-13T16:45:44.477+0000] {taskinstance.py:1935} ERROR - Task failed with exception
Traceback (most recent call last):
  File "/home/airflow/.local/lib/python3.8/site-packages/airflow/operators/python.py", line 192, in execute
    return_value = self.execute_callable()
  File "/home/airflow/.local/lib/python3.8/site-packages/airflow/operators/python.py", line 209, in execute_callable
    return self.python_callable(*self.op_args, **self.op_kwargs)
  File "/opt/airflow/dags/Dag_postgres.py", line 151, in wrangle_population_data
    df_reshaped = pd.melt(df, id_vars=['Country'], var_name='Year', value_name='Total Population')
  File "/home/airflow/.local/lib/python3.8/site-packages/pandas/core/reshape/melt.py", line 56, in melt
    raise ValueError(
ValueError: value_name (Total Population) cannot match an element in the DataFrame columns.
[2023-11-13T16:45:44.671+0000] {taskinstance.py:1398} INFO - Marking task as FAILED. dag_id=covid_data_dag_postgres, task_id=wrangle_population_data, execution_date=20231113T164341, start_date=20231113T164540, end_date=20231113T164544
[2023-11-13T16:45:44.854+0000] {standard_task_runner.py:104} ERROR - Failed to execute job 818 for task wrangle_population_data (value_name (Total Population) cannot match an element in the DataFrame columns.; 476)
[2023-11-13T16:45:44.995+0000] {local_task_job_runner.py:228} INFO - Task exited with return code 1
[2023-11-13T16:45:47.103+0000] {taskinstance.py:2776} INFO - 0 downstream tasks scheduled from follow-on schedule check
