[2023-11-14T18:18:35.470+0000] {taskinstance.py:1157} INFO - Dependencies all met for dep_context=non-requeueable deps ti=<TaskInstance: covid_data_dag_postgres.wrangle_location_data manual__2023-11-14T18:11:19.655016+00:00 [queued]>
[2023-11-14T18:18:35.730+0000] {taskinstance.py:1157} INFO - Dependencies all met for dep_context=requeueable deps ti=<TaskInstance: covid_data_dag_postgres.wrangle_location_data manual__2023-11-14T18:11:19.655016+00:00 [queued]>
[2023-11-14T18:18:35.748+0000] {taskinstance.py:1359} INFO - Starting attempt 2 of 2
[2023-11-14T18:18:36.020+0000] {taskinstance.py:1380} INFO - Executing <Task(PythonOperator): wrangle_location_data> on 2023-11-14 18:11:19.655016+00:00
[2023-11-14T18:18:36.060+0000] {standard_task_runner.py:57} INFO - Started process 18089 to run task
[2023-11-14T18:18:36.081+0000] {standard_task_runner.py:84} INFO - Running: ['***', 'tasks', 'run', 'covid_data_dag_postgres', 'wrangle_location_data', 'manual__2023-11-14T18:11:19.655016+00:00', '--job-id', '946', '--raw', '--subdir', 'DAGS_FOLDER/Dag_postgres.py', '--cfg-path', '/tmp/tmp8_qsqo_w']
[2023-11-14T18:18:36.129+0000] {standard_task_runner.py:85} INFO - Job 946: Subtask wrangle_location_data
[2023-11-14T18:18:42.856+0000] {task_command.py:415} INFO - Running <TaskInstance: covid_data_dag_postgres.wrangle_location_data manual__2023-11-14T18:11:19.655016+00:00 [running]> on host 172.21.0.4
[2023-11-14T18:18:43.173+0000] {taskinstance.py:1660} INFO - Exporting env vars: AIRFLOW_CTX_DAG_OWNER='***' AIRFLOW_CTX_DAG_ID='covid_data_dag_postgres' AIRFLOW_CTX_TASK_ID='wrangle_location_data' AIRFLOW_CTX_EXECUTION_DATE='2023-11-14T18:11:19.655016+00:00' AIRFLOW_CTX_TRY_NUMBER='2' AIRFLOW_CTX_DAG_RUN_ID='manual__2023-11-14T18:11:19.655016+00:00'
[2023-11-14T18:18:43.185+0000] {taskinstance.py:1935} ERROR - Task failed with exception
Traceback (most recent call last):
  File "/home/airflow/.local/lib/python3.8/site-packages/airflow/operators/python.py", line 192, in execute
    return_value = self.execute_callable()
  File "/home/airflow/.local/lib/python3.8/site-packages/airflow/operators/python.py", line 209, in execute_callable
    return self.python_callable(*self.op_args, **self.op_kwargs)
  File "/opt/airflow/dags/Dag_postgres.py", line 178, in wrangle_location_data
    df = pd.read_csv('/opt/airflow/dags/postgres/location.csv')
  File "/home/airflow/.local/lib/python3.8/site-packages/pandas/io/parsers/readers.py", line 912, in read_csv
    return _read(filepath_or_buffer, kwds)
  File "/home/airflow/.local/lib/python3.8/site-packages/pandas/io/parsers/readers.py", line 577, in _read
    parser = TextFileReader(filepath_or_buffer, **kwds)
  File "/home/airflow/.local/lib/python3.8/site-packages/pandas/io/parsers/readers.py", line 1407, in __init__
    self._engine = self._make_engine(f, self.engine)
  File "/home/airflow/.local/lib/python3.8/site-packages/pandas/io/parsers/readers.py", line 1661, in _make_engine
    self.handles = get_handle(
  File "/home/airflow/.local/lib/python3.8/site-packages/pandas/io/common.py", line 859, in get_handle
    handle = open(
FileNotFoundError: [Errno 2] No such file or directory: '/opt/airflow/dags/postgres/location.csv'
[2023-11-14T18:18:43.219+0000] {taskinstance.py:1398} INFO - Marking task as FAILED. dag_id=covid_data_dag_postgres, task_id=wrangle_location_data, execution_date=20231114T181119, start_date=20231114T181835, end_date=20231114T181843
[2023-11-14T18:18:43.255+0000] {standard_task_runner.py:104} ERROR - Failed to execute job 946 for task wrangle_location_data ([Errno 2] No such file or directory: '/opt/airflow/dags/postgres/location.csv'; 18089)
[2023-11-14T18:18:43.315+0000] {local_task_job_runner.py:228} INFO - Task exited with return code 1
[2023-11-14T18:18:43.860+0000] {taskinstance.py:2776} INFO - 0 downstream tasks scheduled from follow-on schedule check
