[2023-11-24T19:11:07.455+0000] {taskinstance.py:1157} INFO - Dependencies all met for dep_context=non-requeueable deps ti=<TaskInstance: covid_data_dag_postgres_plis.staging.wrangle_vaccinations manual__2023-11-24T18:57:23.260150+00:00 [queued]>
[2023-11-24T19:11:07.560+0000] {taskinstance.py:1157} INFO - Dependencies all met for dep_context=requeueable deps ti=<TaskInstance: covid_data_dag_postgres_plis.staging.wrangle_vaccinations manual__2023-11-24T18:57:23.260150+00:00 [queued]>
[2023-11-24T19:11:07.562+0000] {taskinstance.py:1359} INFO - Starting attempt 2 of 2
[2023-11-24T19:11:07.718+0000] {taskinstance.py:1380} INFO - Executing <Task(PythonOperator): staging.wrangle_vaccinations> on 2023-11-24 18:57:23.260150+00:00
[2023-11-24T19:11:08.068+0000] {standard_task_runner.py:57} INFO - Started process 4439 to run task
[2023-11-24T19:11:08.125+0000] {standard_task_runner.py:84} INFO - Running: ['***', 'tasks', 'run', 'covid_data_dag_postgres_plis', 'staging.wrangle_vaccinations', 'manual__2023-11-24T18:57:23.260150+00:00', '--job-id', '1501', '--raw', '--subdir', 'DAGS_FOLDER/Dag_postgres.py', '--cfg-path', '/tmp/tmpf1ggyeiy']
[2023-11-24T19:11:08.166+0000] {standard_task_runner.py:85} INFO - Job 1501: Subtask staging.wrangle_vaccinations
[2023-11-24T19:11:08.590+0000] {task_command.py:415} INFO - Running <TaskInstance: covid_data_dag_postgres_plis.staging.wrangle_vaccinations manual__2023-11-24T18:57:23.260150+00:00 [running]> on host 172.21.0.6
[2023-11-24T19:11:08.980+0000] {taskinstance.py:1660} INFO - Exporting env vars: AIRFLOW_CTX_DAG_OWNER='***' AIRFLOW_CTX_DAG_ID='covid_data_dag_postgres_plis' AIRFLOW_CTX_TASK_ID='staging.wrangle_vaccinations' AIRFLOW_CTX_EXECUTION_DATE='2023-11-24T18:57:23.260150+00:00' AIRFLOW_CTX_TRY_NUMBER='2' AIRFLOW_CTX_DAG_RUN_ID='manual__2023-11-24T18:57:23.260150+00:00'
[2023-11-24T19:11:10.066+0000] {logging_mixin.py:151} INFO - Formatting dateâ€¦
[2023-11-24T19:11:10.075+0000] {taskinstance.py:1935} ERROR - Task failed with exception
Traceback (most recent call last):
  File "/home/airflow/.local/lib/python3.8/site-packages/pandas/core/indexes/base.py", line 3653, in get_loc
    return self._engine.get_loc(casted_key)
  File "pandas/_libs/index.pyx", line 147, in pandas._libs.index.IndexEngine.get_loc
  File "pandas/_libs/index.pyx", line 176, in pandas._libs.index.IndexEngine.get_loc
  File "pandas/_libs/hashtable_class_helper.pxi", line 7080, in pandas._libs.hashtable.PyObjectHashTable.get_item
  File "pandas/_libs/hashtable_class_helper.pxi", line 7088, in pandas._libs.hashtable.PyObjectHashTable.get_item
KeyError: 'Date_reported'

The above exception was the direct cause of the following exception:

Traceback (most recent call last):
  File "/home/airflow/.local/lib/python3.8/site-packages/airflow/operators/python.py", line 192, in execute
    return_value = self.execute_callable()
  File "/home/airflow/.local/lib/python3.8/site-packages/airflow/operators/python.py", line 209, in execute_callable
    return self.python_callable(*self.op_args, **self.op_kwargs)
  File "/opt/airflow/dags/Dag_postgres.py", line 296, in _wrangle_vaccinations
    df = format_date(df)
  File "/opt/airflow/dags/Dag_postgres.py", line 187, in format_date
    df["Date_reported"] = pd.to_datetime(df["Date_reported"], format="%Y-%m-%d")
  File "/home/airflow/.local/lib/python3.8/site-packages/pandas/core/frame.py", line 3761, in __getitem__
    indexer = self.columns.get_loc(key)
  File "/home/airflow/.local/lib/python3.8/site-packages/pandas/core/indexes/base.py", line 3655, in get_loc
    raise KeyError(key) from err
KeyError: 'Date_reported'
[2023-11-24T19:11:10.134+0000] {taskinstance.py:1398} INFO - Marking task as FAILED. dag_id=covid_data_dag_postgres_plis, task_id=staging.wrangle_vaccinations, execution_date=20231124T185723, start_date=20231124T191107, end_date=20231124T191110
[2023-11-24T19:11:10.171+0000] {standard_task_runner.py:104} ERROR - Failed to execute job 1501 for task staging.wrangle_vaccinations ('Date_reported'; 4439)
[2023-11-24T19:11:10.190+0000] {local_task_job_runner.py:228} INFO - Task exited with return code 1
[2023-11-24T19:11:10.246+0000] {taskinstance.py:2776} INFO - 0 downstream tasks scheduled from follow-on schedule check
