[2023-11-23T18:44:28.453+0000] {taskinstance.py:1157} INFO - Dependencies all met for dep_context=non-requeueable deps ti=<TaskInstance: covid_data_dag_postgres_plis.ingestion.store_population_data manual__2023-11-23T18:41:13.508197+00:00 [queued]>
[2023-11-23T18:44:28.573+0000] {taskinstance.py:1157} INFO - Dependencies all met for dep_context=requeueable deps ti=<TaskInstance: covid_data_dag_postgres_plis.ingestion.store_population_data manual__2023-11-23T18:41:13.508197+00:00 [queued]>
[2023-11-23T18:44:28.574+0000] {taskinstance.py:1359} INFO - Starting attempt 2 of 2
[2023-11-23T18:44:28.733+0000] {taskinstance.py:1380} INFO - Executing <Task(PythonOperator): ingestion.store_population_data> on 2023-11-23 18:41:13.508197+00:00
[2023-11-23T18:44:29.036+0000] {standard_task_runner.py:57} INFO - Started process 542 to run task
[2023-11-23T18:44:29.231+0000] {standard_task_runner.py:84} INFO - Running: ['***', 'tasks', 'run', 'covid_data_dag_postgres_plis', 'ingestion.store_population_data', 'manual__2023-11-23T18:41:13.508197+00:00', '--job-id', '1371', '--raw', '--subdir', 'DAGS_FOLDER/Dag_postgres.py', '--cfg-path', '/tmp/tmp6czvk9ip']
[2023-11-23T18:44:29.292+0000] {standard_task_runner.py:85} INFO - Job 1371: Subtask ingestion.store_population_data
[2023-11-23T18:44:32.738+0000] {task_command.py:415} INFO - Running <TaskInstance: covid_data_dag_postgres_plis.ingestion.store_population_data manual__2023-11-23T18:41:13.508197+00:00 [running]> on host 172.21.0.5
[2023-11-23T18:44:37.483+0000] {taskinstance.py:1660} INFO - Exporting env vars: AIRFLOW_CTX_DAG_OWNER='***' AIRFLOW_CTX_DAG_ID='covid_data_dag_postgres_plis' AIRFLOW_CTX_TASK_ID='ingestion.store_population_data' AIRFLOW_CTX_EXECUTION_DATE='2023-11-23T18:41:13.508197+00:00' AIRFLOW_CTX_TRY_NUMBER='2' AIRFLOW_CTX_DAG_RUN_ID='manual__2023-11-23T18:41:13.508197+00:00'
[2023-11-23T18:44:39.348+0000] {taskinstance.py:1935} ERROR - Task failed with exception
Traceback (most recent call last):
  File "/home/airflow/.local/lib/python3.8/site-packages/airflow/operators/python.py", line 192, in execute
    return_value = self.execute_callable()
  File "/home/airflow/.local/lib/python3.8/site-packages/airflow/operators/python.py", line 209, in execute_callable
    return self.python_callable(*self.op_args, **self.op_kwargs)
  File "/opt/airflow/dags/Dag_postgres.py", line 119, in _store_population_data
    collection.insert_many(csv_to_json(population_data))
  File "/opt/airflow/dags/Dag_postgres.py", line 99, in csv_to_json
    data = pd.read_csv(filename, header=header)
  File "/home/airflow/.local/lib/python3.8/site-packages/pandas/io/parsers/readers.py", line 912, in read_csv
    return _read(filepath_or_buffer, kwds)
  File "/home/airflow/.local/lib/python3.8/site-packages/pandas/io/parsers/readers.py", line 577, in _read
    parser = TextFileReader(filepath_or_buffer, **kwds)
  File "/home/airflow/.local/lib/python3.8/site-packages/pandas/io/parsers/readers.py", line 1407, in __init__
    self._engine = self._make_engine(f, self.engine)
  File "/home/airflow/.local/lib/python3.8/site-packages/pandas/io/parsers/readers.py", line 1679, in _make_engine
    return mapping[engine](f, **self.options)
  File "/home/airflow/.local/lib/python3.8/site-packages/pandas/io/parsers/c_parser_wrapper.py", line 93, in __init__
    self._reader = parsers.TextReader(src, **kwds)
  File "pandas/_libs/parsers.pyx", line 550, in pandas._libs.parsers.TextReader.__cinit__
  File "pandas/_libs/parsers.pyx", line 758, in pandas._libs.parsers.TextReader._get_header
  File "pandas/_libs/parsers.pyx", line 850, in pandas._libs.parsers.TextReader._tokenize_rows
  File "pandas/_libs/parsers.pyx", line 861, in pandas._libs.parsers.TextReader._check_tokenize_status
  File "pandas/_libs/parsers.pyx", line 2021, in pandas._libs.parsers.raise_parser_error
UnicodeDecodeError: 'utf-8' codec can't decode byte 0xa7 in position 10: invalid start byte
[2023-11-23T18:44:39.513+0000] {taskinstance.py:1398} INFO - Marking task as FAILED. dag_id=covid_data_dag_postgres_plis, task_id=ingestion.store_population_data, execution_date=20231123T184113, start_date=20231123T184428, end_date=20231123T184439
[2023-11-23T18:44:39.621+0000] {standard_task_runner.py:104} ERROR - Failed to execute job 1371 for task ingestion.store_population_data ('utf-8' codec can't decode byte 0xa7 in position 10: invalid start byte; 542)
[2023-11-23T18:44:39.689+0000] {local_task_job_runner.py:228} INFO - Task exited with return code 1
[2023-11-23T18:44:39.861+0000] {taskinstance.py:2776} INFO - 0 downstream tasks scheduled from follow-on schedule check
