[2023-11-08T11:58:56.980+0000] {taskinstance.py:1157} INFO - Dependencies all met for dep_context=non-requeueable deps ti=<TaskInstance: covid_data_dag.create_vaccinations_query_operator manual__2023-11-08T11:58:28.586316+00:00 [queued]>
[2023-11-08T11:58:56.995+0000] {taskinstance.py:1157} INFO - Dependencies all met for dep_context=requeueable deps ti=<TaskInstance: covid_data_dag.create_vaccinations_query_operator manual__2023-11-08T11:58:28.586316+00:00 [queued]>
[2023-11-08T11:58:56.996+0000] {taskinstance.py:1359} INFO - Starting attempt 2 of 2
[2023-11-08T11:58:57.015+0000] {taskinstance.py:1380} INFO - Executing <Task(PythonOperator): create_vaccinations_query_operator> on 2023-11-08 11:58:28.586316+00:00
[2023-11-08T11:58:57.021+0000] {standard_task_runner.py:57} INFO - Started process 1535 to run task
[2023-11-08T11:58:57.025+0000] {standard_task_runner.py:84} INFO - Running: ['***', 'tasks', 'run', 'covid_data_dag', 'create_vaccinations_query_operator', 'manual__2023-11-08T11:58:28.586316+00:00', '--job-id', '273', '--raw', '--subdir', 'DAGS_FOLDER/Dag_postgres.py', '--cfg-path', '/tmp/tmpq9iyuwh2']
[2023-11-08T11:58:57.029+0000] {standard_task_runner.py:85} INFO - Job 273: Subtask create_vaccinations_query_operator
[2023-11-08T11:58:57.079+0000] {task_command.py:415} INFO - Running <TaskInstance: covid_data_dag.create_vaccinations_query_operator manual__2023-11-08T11:58:28.586316+00:00 [running]> on host 172.21.0.9
[2023-11-08T11:58:57.131+0000] {warnings.py:109} WARNING - /home/***/.local/lib/python3.8/site-packages/***/utils/context.py:206: AirflowContextDeprecationWarning: Accessing 'prev_execution_date' from the template is deprecated and will be removed in a future version.
  warnings.warn(_create_deprecation_warning(key, self._deprecation_replacements[key]))

[2023-11-08T11:58:57.174+0000] {taskinstance.py:1660} INFO - Exporting env vars: AIRFLOW_CTX_DAG_OWNER='***' AIRFLOW_CTX_DAG_ID='covid_data_dag' AIRFLOW_CTX_TASK_ID='create_vaccinations_query_operator' AIRFLOW_CTX_EXECUTION_DATE='2023-11-08T11:58:28.586316+00:00' AIRFLOW_CTX_TRY_NUMBER='2' AIRFLOW_CTX_DAG_RUN_ID='manual__2023-11-08T11:58:28.586316+00:00'
[2023-11-08T11:58:57.699+0000] {taskinstance.py:1935} ERROR - Task failed with exception
Traceback (most recent call last):
  File "/home/airflow/.local/lib/python3.8/site-packages/pandas/core/indexes/base.py", line 3653, in get_loc
    return self._engine.get_loc(casted_key)
  File "pandas/_libs/index.pyx", line 147, in pandas._libs.index.IndexEngine.get_loc
  File "pandas/_libs/index.pyx", line 176, in pandas._libs.index.IndexEngine.get_loc
  File "pandas/_libs/hashtable_class_helper.pxi", line 7080, in pandas._libs.hashtable.PyObjectHashTable.get_item
  File "pandas/_libs/hashtable_class_helper.pxi", line 7088, in pandas._libs.hashtable.PyObjectHashTable.get_item
KeyError: 'vaccines'

The above exception was the direct cause of the following exception:

Traceback (most recent call last):
  File "/home/airflow/.local/lib/python3.8/site-packages/airflow/operators/python.py", line 192, in execute
    return_value = self.execute_callable()
  File "/home/airflow/.local/lib/python3.8/site-packages/airflow/operators/python.py", line 209, in execute_callable
    return self.python_callable(*self.op_args, **self.op_kwargs)
  File "/opt/airflow/dags/Dag_postgres.py", line 124, in _create_vaccinations_query
    vaccines = row['vaccines'].replace("'", "''")
  File "/home/airflow/.local/lib/python3.8/site-packages/pandas/core/series.py", line 1007, in __getitem__
    return self._get_value(key)
  File "/home/airflow/.local/lib/python3.8/site-packages/pandas/core/series.py", line 1116, in _get_value
    loc = self.index.get_loc(label)
  File "/home/airflow/.local/lib/python3.8/site-packages/pandas/core/indexes/base.py", line 3655, in get_loc
    raise KeyError(key) from err
KeyError: 'vaccines'
[2023-11-08T11:58:57.715+0000] {taskinstance.py:1398} INFO - Marking task as FAILED. dag_id=covid_data_dag, task_id=create_vaccinations_query_operator, execution_date=20231108T115828, start_date=20231108T115856, end_date=20231108T115857
[2023-11-08T11:58:57.731+0000] {standard_task_runner.py:104} ERROR - Failed to execute job 273 for task create_vaccinations_query_operator ('vaccines'; 1535)
[2023-11-08T11:58:57.777+0000] {local_task_job_runner.py:228} INFO - Task exited with return code 1
[2023-11-08T11:58:57.805+0000] {taskinstance.py:2776} INFO - 0 downstream tasks scheduled from follow-on schedule check
