[2023-11-07T10:12:43.287+0000] {taskinstance.py:1157} INFO - Dependencies all met for dep_context=non-requeueable deps ti=<TaskInstance: covid_data_dag.store_vaccinations manual__2023-11-07T10:12:20.296729+00:00 [queued]>
[2023-11-07T10:12:43.316+0000] {taskinstance.py:1157} INFO - Dependencies all met for dep_context=requeueable deps ti=<TaskInstance: covid_data_dag.store_vaccinations manual__2023-11-07T10:12:20.296729+00:00 [queued]>
[2023-11-07T10:12:43.316+0000] {taskinstance.py:1359} INFO - Starting attempt 2 of 2
[2023-11-07T10:12:43.363+0000] {taskinstance.py:1380} INFO - Executing <Task(PythonOperator): store_vaccinations> on 2023-11-07 10:12:20.296729+00:00
[2023-11-07T10:12:43.405+0000] {standard_task_runner.py:57} INFO - Started process 769 to run task
[2023-11-07T10:12:43.421+0000] {standard_task_runner.py:84} INFO - Running: ['***', 'tasks', 'run', 'covid_data_dag', 'store_vaccinations', 'manual__2023-11-07T10:12:20.296729+00:00', '--job-id', '26', '--raw', '--subdir', 'DAGS_FOLDER/Dags.py', '--cfg-path', '/tmp/tmp31v9rfuz']
[2023-11-07T10:12:43.452+0000] {standard_task_runner.py:85} INFO - Job 26: Subtask store_vaccinations
[2023-11-07T10:12:44.527+0000] {task_command.py:415} INFO - Running <TaskInstance: covid_data_dag.store_vaccinations manual__2023-11-07T10:12:20.296729+00:00 [running]> on host 172.21.0.8
[2023-11-07T10:12:45.564+0000] {taskinstance.py:1660} INFO - Exporting env vars: AIRFLOW_CTX_DAG_OWNER='***' AIRFLOW_CTX_DAG_ID='covid_data_dag' AIRFLOW_CTX_TASK_ID='store_vaccinations' AIRFLOW_CTX_EXECUTION_DATE='2023-11-07T10:12:20.296729+00:00' AIRFLOW_CTX_TRY_NUMBER='2' AIRFLOW_CTX_DAG_RUN_ID='manual__2023-11-07T10:12:20.296729+00:00'
[2023-11-07T10:12:47.010+0000] {taskinstance.py:1935} ERROR - Task failed with exception
Traceback (most recent call last):
  File "/home/airflow/.local/lib/python3.8/site-packages/airflow/operators/python.py", line 192, in execute
    return_value = self.execute_callable()
  File "/home/airflow/.local/lib/python3.8/site-packages/airflow/operators/python.py", line 209, in execute_callable
    return self.python_callable(*self.op_args, **self.op_kwargs)
  File "/opt/airflow/dags/Dags.py", line 65, in store_vaccinations
    collection.insert_many(data)
  File "/home/airflow/.local/lib/python3.8/site-packages/pymongo/_csot.py", line 107, in csot_wrapper
    return func(self, *args, **kwargs)
  File "/home/airflow/.local/lib/python3.8/site-packages/pymongo/collection.py", line 739, in insert_many
    raise TypeError("documents must be a non-empty list")
TypeError: documents must be a non-empty list
[2023-11-07T10:12:47.139+0000] {taskinstance.py:1398} INFO - Marking task as FAILED. dag_id=covid_data_dag, task_id=store_vaccinations, execution_date=20231107T101220, start_date=20231107T101243, end_date=20231107T101247
[2023-11-07T10:12:47.262+0000] {standard_task_runner.py:104} ERROR - Failed to execute job 26 for task store_vaccinations (documents must be a non-empty list; 769)
[2023-11-07T10:12:47.359+0000] {local_task_job_runner.py:228} INFO - Task exited with return code 1
[2023-11-07T10:12:47.446+0000] {taskinstance.py:2776} INFO - 0 downstream tasks scheduled from follow-on schedule check
