[2023-11-16T00:11:52.514+0000] {taskinstance.py:1157} INFO - Dependencies all met for dep_context=non-requeueable deps ti=<TaskInstance: covid_data_dag_postgres_plis.ingestion.download_population_data scheduled__2023-11-15T00:00:00+00:00 [queued]>
[2023-11-16T00:11:52.560+0000] {taskinstance.py:1157} INFO - Dependencies all met for dep_context=requeueable deps ti=<TaskInstance: covid_data_dag_postgres_plis.ingestion.download_population_data scheduled__2023-11-15T00:00:00+00:00 [queued]>
[2023-11-16T00:11:52.563+0000] {taskinstance.py:1359} INFO - Starting attempt 1 of 2
[2023-11-16T00:11:52.631+0000] {taskinstance.py:1380} INFO - Executing <Task(PythonOperator): ingestion.download_population_data> on 2023-11-15 00:00:00+00:00
[2023-11-16T00:11:52.661+0000] {standard_task_runner.py:57} INFO - Started process 12717 to run task
[2023-11-16T00:11:52.686+0000] {standard_task_runner.py:84} INFO - Running: ['***', 'tasks', 'run', 'covid_data_dag_postgres_plis', 'ingestion.download_population_data', 'scheduled__2023-11-15T00:00:00+00:00', '--job-id', '1095', '--raw', '--subdir', 'DAGS_FOLDER/Dag_postgres.py', '--cfg-path', '/tmp/tmplj5v2t5o']
[2023-11-16T00:11:52.714+0000] {standard_task_runner.py:85} INFO - Job 1095: Subtask ingestion.download_population_data
[2023-11-16T00:11:57.137+0000] {task_command.py:415} INFO - Running <TaskInstance: covid_data_dag_postgres_plis.ingestion.download_population_data scheduled__2023-11-15T00:00:00+00:00 [running]> on host 172.21.0.9
[2023-11-16T00:11:57.139+0000] {warnings.py:109} WARNING - /home/***/.local/lib/python3.8/site-packages/***/settings.py:346: DeprecationWarning: The sql_engine_encoding option in [core] has been moved to the sql_engine_encoding option in [database] - the old setting has been used, but please update your config.
  engine_args["encoding"] = conf.get("database", "SQL_ENGINE_ENCODING", fallback="utf-8")

[2023-11-16T00:11:57.315+0000] {taskinstance.py:1660} INFO - Exporting env vars: AIRFLOW_CTX_DAG_OWNER='***' AIRFLOW_CTX_DAG_ID='covid_data_dag_postgres_plis' AIRFLOW_CTX_TASK_ID='ingestion.download_population_data' AIRFLOW_CTX_EXECUTION_DATE='2023-11-15T00:00:00+00:00' AIRFLOW_CTX_TRY_NUMBER='1' AIRFLOW_CTX_DAG_RUN_ID='scheduled__2023-11-15T00:00:00+00:00'
[2023-11-16T00:11:57.333+0000] {taskinstance.py:1935} ERROR - Task failed with exception
Traceback (most recent call last):
  File "/home/airflow/.local/lib/python3.8/site-packages/urllib3/connection.py", line 174, in _new_conn
    conn = connection.create_connection(
  File "/home/airflow/.local/lib/python3.8/site-packages/urllib3/util/connection.py", line 72, in create_connection
    for res in socket.getaddrinfo(host, port, family, socket.SOCK_STREAM):
  File "/usr/local/lib/python3.8/socket.py", line 918, in getaddrinfo
    for res in _socket.getaddrinfo(host, port, family, type, proto, flags):
socket.gaierror: [Errno -2] Name or service not known

During handling of the above exception, another exception occurred:

Traceback (most recent call last):
  File "/home/airflow/.local/lib/python3.8/site-packages/urllib3/connectionpool.py", line 714, in urlopen
    httplib_response = self._make_request(
  File "/home/airflow/.local/lib/python3.8/site-packages/urllib3/connectionpool.py", line 403, in _make_request
    self._validate_conn(conn)
  File "/home/airflow/.local/lib/python3.8/site-packages/urllib3/connectionpool.py", line 1053, in _validate_conn
    conn.connect()
  File "/home/airflow/.local/lib/python3.8/site-packages/urllib3/connection.py", line 363, in connect
    self.sock = conn = self._new_conn()
  File "/home/airflow/.local/lib/python3.8/site-packages/urllib3/connection.py", line 186, in _new_conn
    raise NewConnectionError(
urllib3.exceptions.NewConnectionError: <urllib3.connection.HTTPSConnection object at 0x7f72a96d3100>: Failed to establish a new connection: [Errno -2] Name or service not known

During handling of the above exception, another exception occurred:

Traceback (most recent call last):
  File "/home/airflow/.local/lib/python3.8/site-packages/requests/adapters.py", line 486, in send
    resp = conn.urlopen(
  File "/home/airflow/.local/lib/python3.8/site-packages/urllib3/connectionpool.py", line 798, in urlopen
    retries = retries.increment(
  File "/home/airflow/.local/lib/python3.8/site-packages/urllib3/util/retry.py", line 592, in increment
    raise MaxRetryError(_pool, url, error or ResponseError(cause))
urllib3.exceptions.MaxRetryError: HTTPSConnectionPool(host='api.worldbank.org', port=443): Max retries exceeded with url: /v2/en/sources/2/concepts?per_page=1000&page=1&format=json (Caused by NewConnectionError('<urllib3.connection.HTTPSConnection object at 0x7f72a96d3100>: Failed to establish a new connection: [Errno -2] Name or service not known'))

During handling of the above exception, another exception occurred:

Traceback (most recent call last):
  File "/home/airflow/.local/lib/python3.8/site-packages/airflow/operators/python.py", line 192, in execute
    return_value = self.execute_callable()
  File "/home/airflow/.local/lib/python3.8/site-packages/airflow/operators/python.py", line 209, in execute_callable
    return self.python_callable(*self.op_args, **self.op_kwargs)
  File "/opt/airflow/dags/Dag_postgres.py", line 83, in _download_population_data
    data = wb.data.DataFrame('SP.POP.TOTL', labels=True, time=range(2019, 2023))
  File "/home/airflow/.local/lib/python3.8/site-packages/wbgapi/data.py", line 256, in DataFrame
    for k,v in w.source.concepts(db).items():
  File "/home/airflow/.local/lib/python3.8/site-packages/wbgapi/source.py", line 96, in concepts
    for row in w.fetch(url, concepts=True):
  File "/home/airflow/.local/lib/python3.8/site-packages/wbgapi/__init__.py", line 281, in fetch
    (hdr,result) = _queryAPI(url_)
  File "/home/airflow/.local/lib/python3.8/site-packages/wbgapi/__init__.py", line 528, in _queryAPI
    response = requests.get(url, **params)
  File "/home/airflow/.local/lib/python3.8/site-packages/requests/api.py", line 73, in get
    return request("get", url, params=params, **kwargs)
  File "/home/airflow/.local/lib/python3.8/site-packages/requests/api.py", line 59, in request
    return session.request(method=method, url=url, **kwargs)
  File "/home/airflow/.local/lib/python3.8/site-packages/requests/sessions.py", line 589, in request
    resp = self.send(prep, **send_kwargs)
  File "/home/airflow/.local/lib/python3.8/site-packages/requests/sessions.py", line 703, in send
    r = adapter.send(request, **kwargs)
  File "/home/airflow/.local/lib/python3.8/site-packages/requests/adapters.py", line 519, in send
    raise ConnectionError(e, request=request)
requests.exceptions.ConnectionError: HTTPSConnectionPool(host='api.worldbank.org', port=443): Max retries exceeded with url: /v2/en/sources/2/concepts?per_page=1000&page=1&format=json (Caused by NewConnectionError('<urllib3.connection.HTTPSConnection object at 0x7f72a96d3100>: Failed to establish a new connection: [Errno -2] Name or service not known'))
[2023-11-16T00:11:57.368+0000] {taskinstance.py:1398} INFO - Marking task as UP_FOR_RETRY. dag_id=covid_data_dag_postgres_plis, task_id=ingestion.download_population_data, execution_date=20231115T000000, start_date=20231116T001152, end_date=20231116T001157
[2023-11-16T00:11:57.395+0000] {standard_task_runner.py:104} ERROR - Failed to execute job 1095 for task ingestion.download_population_data (HTTPSConnectionPool(host='api.worldbank.org', port=443): Max retries exceeded with url: /v2/en/sources/2/concepts?per_page=1000&page=1&format=json (Caused by NewConnectionError('<urllib3.connection.HTTPSConnection object at 0x7f72a96d3100>: Failed to establish a new connection: [Errno -2] Name or service not known')); 12717)
[2023-11-16T00:11:57.457+0000] {local_task_job_runner.py:228} INFO - Task exited with return code 1
[2023-11-16T00:11:59.494+0000] {taskinstance.py:2776} INFO - 0 downstream tasks scheduled from follow-on schedule check
