[2023-11-09T11:47:48.679+0000] {taskinstance.py:1157} INFO - Dependencies all met for dep_context=non-requeueable deps ti=<TaskInstance: covid_data_dag_mongo.create_vaccinations_query_operator manual__2023-11-09T11:46:30.201549+00:00 [queued]>
[2023-11-09T11:47:48.696+0000] {taskinstance.py:1157} INFO - Dependencies all met for dep_context=requeueable deps ti=<TaskInstance: covid_data_dag_mongo.create_vaccinations_query_operator manual__2023-11-09T11:46:30.201549+00:00 [queued]>
[2023-11-09T11:47:48.697+0000] {taskinstance.py:1359} INFO - Starting attempt 2 of 2
[2023-11-09T11:47:49.334+0000] {taskinstance.py:1380} INFO - Executing <Task(PythonOperator): create_vaccinations_query_operator> on 2023-11-09 11:46:30.201549+00:00
[2023-11-09T11:47:49.343+0000] {standard_task_runner.py:57} INFO - Started process 2147 to run task
[2023-11-09T11:47:49.352+0000] {standard_task_runner.py:84} INFO - Running: ['***', 'tasks', 'run', 'covid_data_dag_mongo', 'create_vaccinations_query_operator', 'manual__2023-11-09T11:46:30.201549+00:00', '--job-id', '729', '--raw', '--subdir', 'DAGS_FOLDER/Dag_mongo.py', '--cfg-path', '/tmp/tmpwlxwy8gb']
[2023-11-09T11:47:49.357+0000] {standard_task_runner.py:85} INFO - Job 729: Subtask create_vaccinations_query_operator
[2023-11-09T11:47:49.458+0000] {task_command.py:415} INFO - Running <TaskInstance: covid_data_dag_mongo.create_vaccinations_query_operator manual__2023-11-09T11:46:30.201549+00:00 [running]> on host 172.21.0.7
[2023-11-09T11:47:49.511+0000] {warnings.py:109} WARNING - /home/***/.local/lib/python3.8/site-packages/***/utils/context.py:206: AirflowContextDeprecationWarning: Accessing 'prev_execution_date' from the template is deprecated and will be removed in a future version.
  warnings.warn(_create_deprecation_warning(key, self._deprecation_replacements[key]))

[2023-11-09T11:47:49.554+0000] {taskinstance.py:1660} INFO - Exporting env vars: AIRFLOW_CTX_DAG_OWNER='***' AIRFLOW_CTX_DAG_ID='covid_data_dag_mongo' AIRFLOW_CTX_TASK_ID='create_vaccinations_query_operator' AIRFLOW_CTX_EXECUTION_DATE='2023-11-09T11:46:30.201549+00:00' AIRFLOW_CTX_TRY_NUMBER='2' AIRFLOW_CTX_DAG_RUN_ID='manual__2023-11-09T11:46:30.201549+00:00'
[2023-11-09T11:48:25.561+0000] {taskinstance.py:1935} ERROR - Task failed with exception
Traceback (most recent call last):
  File "/home/airflow/.local/lib/python3.8/site-packages/airflow/operators/python.py", line 192, in execute
    return_value = self.execute_callable()
  File "/home/airflow/.local/lib/python3.8/site-packages/airflow/operators/python.py", line 209, in execute_callable
    return self.python_callable(*self.op_args, **self.op_kwargs)
  File "/opt/airflow/dags/Dag_mongo.py", line 68, in _create_vaccinations_query
    collection.insert_many(df.to_dict('records'))
  File "/home/airflow/.local/lib/python3.8/site-packages/pymongo/_csot.py", line 107, in csot_wrapper
    return func(self, *args, **kwargs)
  File "/home/airflow/.local/lib/python3.8/site-packages/pymongo/collection.py", line 755, in insert_many
    blk.execute(write_concern, session=session)
  File "/home/airflow/.local/lib/python3.8/site-packages/pymongo/bulk.py", line 576, in execute
    return self.execute_command(generator, write_concern, session)
  File "/home/airflow/.local/lib/python3.8/site-packages/pymongo/bulk.py", line 443, in execute_command
    client._retryable_write(self.is_retryable, retryable_bulk, session, bulk=self)
  File "/home/airflow/.local/lib/python3.8/site-packages/pymongo/mongo_client.py", line 1522, in _retryable_write
    with self._tmp_session(session) as s:
  File "/usr/local/lib/python3.8/contextlib.py", line 113, in __enter__
    return next(self.gen)
  File "/home/airflow/.local/lib/python3.8/site-packages/pymongo/mongo_client.py", line 1840, in _tmp_session
    s = self._ensure_session(session)
  File "/home/airflow/.local/lib/python3.8/site-packages/pymongo/mongo_client.py", line 1823, in _ensure_session
    return self.__start_session(True, causal_consistency=False)
  File "/home/airflow/.local/lib/python3.8/site-packages/pymongo/mongo_client.py", line 1766, in __start_session
    self._topology._check_implicit_session_support()
  File "/home/airflow/.local/lib/python3.8/site-packages/pymongo/topology.py", line 573, in _check_implicit_session_support
    self._check_session_support()
  File "/home/airflow/.local/lib/python3.8/site-packages/pymongo/topology.py", line 589, in _check_session_support
    self._select_servers_loop(
  File "/home/airflow/.local/lib/python3.8/site-packages/pymongo/topology.py", line 259, in _select_servers_loop
    raise ServerSelectionTimeoutError(
pymongo.errors.ServerSelectionTimeoutError: localhost:27017: [Errno 111] Connection refused (configured timeouts: socketTimeoutMS: 20000.0ms, connectTimeoutMS: 20000.0ms), Timeout: 30s, Topology Description: <TopologyDescription id: 654cc6e6bc511e685e6937bf, topology_type: Unknown, servers: [<ServerDescription ('localhost', 27017) server_type: Unknown, rtt: None, error=AutoReconnect('localhost:27017: [Errno 111] Connection refused (configured timeouts: socketTimeoutMS: 20000.0ms, connectTimeoutMS: 20000.0ms)')>]>
[2023-11-09T11:48:25.597+0000] {taskinstance.py:1398} INFO - Marking task as FAILED. dag_id=covid_data_dag_mongo, task_id=create_vaccinations_query_operator, execution_date=20231109T114630, start_date=20231109T114748, end_date=20231109T114825
[2023-11-09T11:48:25.635+0000] {standard_task_runner.py:104} ERROR - Failed to execute job 729 for task create_vaccinations_query_operator (localhost:27017: [Errno 111] Connection refused (configured timeouts: socketTimeoutMS: 20000.0ms, connectTimeoutMS: 20000.0ms), Timeout: 30s, Topology Description: <TopologyDescription id: 654cc6e6bc511e685e6937bf, topology_type: Unknown, servers: [<ServerDescription ('localhost', 27017) server_type: Unknown, rtt: None, error=AutoReconnect('localhost:27017: [Errno 111] Connection refused (configured timeouts: socketTimeoutMS: 20000.0ms, connectTimeoutMS: 20000.0ms)')>]>; 2147)
[2023-11-09T11:48:25.731+0000] {local_task_job_runner.py:228} INFO - Task exited with return code 1
[2023-11-09T11:48:25.753+0000] {taskinstance.py:2776} INFO - 0 downstream tasks scheduled from follow-on schedule check
