[2023-11-08T13:13:55.284+0000] {taskinstance.py:1157} INFO - Dependencies all met for dep_context=non-requeueable deps ti=<TaskInstance: covid_data_dag.store_cases_deaths manual__2023-11-08T13:11:55.720846+00:00 [queued]>
[2023-11-08T13:13:55.316+0000] {taskinstance.py:1157} INFO - Dependencies all met for dep_context=requeueable deps ti=<TaskInstance: covid_data_dag.store_cases_deaths manual__2023-11-08T13:11:55.720846+00:00 [queued]>
[2023-11-08T13:13:55.317+0000] {taskinstance.py:1359} INFO - Starting attempt 2 of 2
[2023-11-08T13:13:55.370+0000] {taskinstance.py:1380} INFO - Executing <Task(PostgresOperator): store_cases_deaths> on 2023-11-08 13:11:55.720846+00:00
[2023-11-08T13:13:55.390+0000] {standard_task_runner.py:57} INFO - Started process 4669 to run task
[2023-11-08T13:13:55.412+0000] {standard_task_runner.py:84} INFO - Running: ['***', 'tasks', 'run', 'covid_data_dag', 'store_cases_deaths', 'manual__2023-11-08T13:11:55.720846+00:00', '--job-id', '472', '--raw', '--subdir', 'DAGS_FOLDER/Dag_postgres.py', '--cfg-path', '/tmp/tmp4bds926n']
[2023-11-08T13:13:55.422+0000] {standard_task_runner.py:85} INFO - Job 472: Subtask store_cases_deaths
[2023-11-08T13:13:55.563+0000] {task_command.py:415} INFO - Running <TaskInstance: covid_data_dag.store_cases_deaths manual__2023-11-08T13:11:55.720846+00:00 [running]> on host 172.21.0.9
[2023-11-08T13:13:55.745+0000] {abstractoperator.py:709} ERROR - Exception rendering Jinja template for task 'store_cases_deaths', field 'sql'. Template: 'INSERT INTO cases_deaths (date_reported, country_code, country, who_region, new_cases, cumulative_cases, new_deaths, cumulative_deaths) SELECT Date_reported, Country_code, Country, WHO_region, New_cases, Cumulative_cases, New_deaths, Cumulative_deaths FROM csv \'{{"/opt/***/dags/cases_deaths.csv"|filename}}\' WITH (FORMAT csv, HEADER true)'
Traceback (most recent call last):
  File "/home/airflow/.local/lib/python3.8/site-packages/airflow/models/abstractoperator.py", line 701, in _do_render_template_fields
    rendered_content = self.render_template(
  File "/home/airflow/.local/lib/python3.8/site-packages/airflow/template/templater.py", line 156, in render_template
    template = jinja_env.from_string(value)
  File "/home/airflow/.local/lib/python3.8/site-packages/jinja2/environment.py", line 1105, in from_string
    return cls.from_code(self, self.compile(source), gs, None)
  File "/home/airflow/.local/lib/python3.8/site-packages/jinja2/environment.py", line 768, in compile
    self.handle_exception(source=source_hint)
  File "/home/airflow/.local/lib/python3.8/site-packages/jinja2/environment.py", line 936, in handle_exception
    raise rewrite_traceback_stack(source=source)
  File "<unknown>", line 1, in template
jinja2.exceptions.TemplateAssertionError: No filter named 'filename'.
[2023-11-08T13:13:55.748+0000] {taskinstance.py:1935} ERROR - Task failed with exception
Traceback (most recent call last):
  File "/home/airflow/.local/lib/python3.8/site-packages/airflow/models/taskinstance.py", line 1516, in _run_raw_task
    self._execute_task_with_callbacks(context, test_mode, session=session)
  File "/home/airflow/.local/lib/python3.8/site-packages/airflow/models/taskinstance.py", line 1645, in _execute_task_with_callbacks
    task_orig = self.render_templates(context=context)
  File "/home/airflow/.local/lib/python3.8/site-packages/airflow/models/taskinstance.py", line 2283, in render_templates
    original_task.render_template_fields(context)
  File "/home/airflow/.local/lib/python3.8/site-packages/airflow/models/baseoperator.py", line 1245, in render_template_fields
    self._do_render_template_fields(self, self.template_fields, context, jinja_env, set())
  File "/home/airflow/.local/lib/python3.8/site-packages/airflow/utils/session.py", line 77, in wrapper
    return func(*args, session=session, **kwargs)
  File "/home/airflow/.local/lib/python3.8/site-packages/airflow/models/abstractoperator.py", line 701, in _do_render_template_fields
    rendered_content = self.render_template(
  File "/home/airflow/.local/lib/python3.8/site-packages/airflow/template/templater.py", line 156, in render_template
    template = jinja_env.from_string(value)
  File "/home/airflow/.local/lib/python3.8/site-packages/jinja2/environment.py", line 1105, in from_string
    return cls.from_code(self, self.compile(source), gs, None)
  File "/home/airflow/.local/lib/python3.8/site-packages/jinja2/environment.py", line 768, in compile
    self.handle_exception(source=source_hint)
  File "/home/airflow/.local/lib/python3.8/site-packages/jinja2/environment.py", line 936, in handle_exception
    raise rewrite_traceback_stack(source=source)
  File "<unknown>", line 1, in template
jinja2.exceptions.TemplateAssertionError: No filter named 'filename'.
[2023-11-08T13:13:55.762+0000] {taskinstance.py:1398} INFO - Marking task as FAILED. dag_id=covid_data_dag, task_id=store_cases_deaths, execution_date=20231108T131155, start_date=20231108T131355, end_date=20231108T131355
[2023-11-08T13:13:55.801+0000] {standard_task_runner.py:104} ERROR - Failed to execute job 472 for task store_cases_deaths (No filter named 'filename'.; 4669)
[2023-11-08T13:13:55.863+0000] {local_task_job_runner.py:228} INFO - Task exited with return code 1
[2023-11-08T13:13:55.893+0000] {taskinstance.py:2776} INFO - 0 downstream tasks scheduled from follow-on schedule check
