[2023-11-07T10:08:08.561+0000] {taskinstance.py:1157} INFO - Dependencies all met for dep_context=non-requeueable deps ti=<TaskInstance: covid_data_dag.store_government_measures manual__2023-11-07T10:07:52.390735+00:00 [queued]>
[2023-11-07T10:08:08.603+0000] {taskinstance.py:1157} INFO - Dependencies all met for dep_context=requeueable deps ti=<TaskInstance: covid_data_dag.store_government_measures manual__2023-11-07T10:07:52.390735+00:00 [queued]>
[2023-11-07T10:08:08.604+0000] {taskinstance.py:1359} INFO - Starting attempt 1 of 2
[2023-11-07T10:08:08.650+0000] {taskinstance.py:1380} INFO - Executing <Task(PythonOperator): store_government_measures> on 2023-11-07 10:07:52.390735+00:00
[2023-11-07T10:08:08.658+0000] {standard_task_runner.py:57} INFO - Started process 553 to run task
[2023-11-07T10:08:08.676+0000] {standard_task_runner.py:84} INFO - Running: ['***', 'tasks', 'run', 'covid_data_dag', 'store_government_measures', 'manual__2023-11-07T10:07:52.390735+00:00', '--job-id', '16', '--raw', '--subdir', 'DAGS_FOLDER/Dags.py', '--cfg-path', '/tmp/tmphvjcebrv']
[2023-11-07T10:08:08.684+0000] {standard_task_runner.py:85} INFO - Job 16: Subtask store_government_measures
[2023-11-07T10:08:08.910+0000] {task_command.py:415} INFO - Running <TaskInstance: covid_data_dag.store_government_measures manual__2023-11-07T10:07:52.390735+00:00 [running]> on host 172.21.0.8
[2023-11-07T10:08:09.227+0000] {taskinstance.py:1660} INFO - Exporting env vars: AIRFLOW_CTX_DAG_OWNER='***' AIRFLOW_CTX_DAG_ID='covid_data_dag' AIRFLOW_CTX_TASK_ID='store_government_measures' AIRFLOW_CTX_EXECUTION_DATE='2023-11-07T10:07:52.390735+00:00' AIRFLOW_CTX_TRY_NUMBER='1' AIRFLOW_CTX_DAG_RUN_ID='manual__2023-11-07T10:07:52.390735+00:00'
[2023-11-07T10:09:02.709+0000] {taskinstance.py:1935} ERROR - Task failed with exception
Traceback (most recent call last):
  File "/home/airflow/.local/lib/python3.8/site-packages/airflow/operators/python.py", line 192, in execute
    return_value = self.execute_callable()
  File "/home/airflow/.local/lib/python3.8/site-packages/airflow/operators/python.py", line 209, in execute_callable
    return self.python_callable(*self.op_args, **self.op_kwargs)
  File "/opt/airflow/dags/Dags.py", line 73, in store_government_measures
    collection.insert_many(data)
  File "/home/airflow/.local/lib/python3.8/site-packages/pymongo/_csot.py", line 107, in csot_wrapper
    return func(self, *args, **kwargs)
  File "/home/airflow/.local/lib/python3.8/site-packages/pymongo/collection.py", line 755, in insert_many
    blk.execute(write_concern, session=session)
  File "/home/airflow/.local/lib/python3.8/site-packages/pymongo/bulk.py", line 576, in execute
    return self.execute_command(generator, write_concern, session)
  File "/home/airflow/.local/lib/python3.8/site-packages/pymongo/bulk.py", line 443, in execute_command
    client._retryable_write(self.is_retryable, retryable_bulk, session, bulk=self)
  File "/home/airflow/.local/lib/python3.8/site-packages/pymongo/mongo_client.py", line 1522, in _retryable_write
    with self._tmp_session(session) as s:
  File "/usr/local/lib/python3.8/contextlib.py", line 113, in __enter__
    return next(self.gen)
  File "/home/airflow/.local/lib/python3.8/site-packages/pymongo/mongo_client.py", line 1840, in _tmp_session
    s = self._ensure_session(session)
  File "/home/airflow/.local/lib/python3.8/site-packages/pymongo/mongo_client.py", line 1823, in _ensure_session
    return self.__start_session(True, causal_consistency=False)
  File "/home/airflow/.local/lib/python3.8/site-packages/pymongo/mongo_client.py", line 1766, in __start_session
    self._topology._check_implicit_session_support()
  File "/home/airflow/.local/lib/python3.8/site-packages/pymongo/topology.py", line 573, in _check_implicit_session_support
    self._check_session_support()
  File "/home/airflow/.local/lib/python3.8/site-packages/pymongo/topology.py", line 589, in _check_session_support
    self._select_servers_loop(
  File "/home/airflow/.local/lib/python3.8/site-packages/pymongo/topology.py", line 259, in _select_servers_loop
    raise ServerSelectionTimeoutError(
pymongo.errors.ServerSelectionTimeoutError: localhost:27017: [Errno 111] Connection refused (configured timeouts: socketTimeoutMS: 20000.0ms, connectTimeoutMS: 20000.0ms), Timeout: 30s, Topology Description: <TopologyDescription id: 654a0c893c5c3664bf3385b1, topology_type: Unknown, servers: [<ServerDescription ('localhost', 27017) server_type: Unknown, rtt: None, error=AutoReconnect('localhost:27017: [Errno 111] Connection refused (configured timeouts: socketTimeoutMS: 20000.0ms, connectTimeoutMS: 20000.0ms)')>]>
[2023-11-07T10:09:02.737+0000] {taskinstance.py:1398} INFO - Marking task as UP_FOR_RETRY. dag_id=covid_data_dag, task_id=store_government_measures, execution_date=20231107T100752, start_date=20231107T100808, end_date=20231107T100902
[2023-11-07T10:09:02.760+0000] {standard_task_runner.py:104} ERROR - Failed to execute job 16 for task store_government_measures (localhost:27017: [Errno 111] Connection refused (configured timeouts: socketTimeoutMS: 20000.0ms, connectTimeoutMS: 20000.0ms), Timeout: 30s, Topology Description: <TopologyDescription id: 654a0c893c5c3664bf3385b1, topology_type: Unknown, servers: [<ServerDescription ('localhost', 27017) server_type: Unknown, rtt: None, error=AutoReconnect('localhost:27017: [Errno 111] Connection refused (configured timeouts: socketTimeoutMS: 20000.0ms, connectTimeoutMS: 20000.0ms)')>]>; 553)
[2023-11-07T10:09:02.914+0000] {local_task_job_runner.py:228} INFO - Task exited with return code 1
[2023-11-07T10:09:02.953+0000] {taskinstance.py:2776} INFO - 0 downstream tasks scheduled from follow-on schedule check
