[2023-11-09T10:20:25.334+0000] {taskinstance.py:1157} INFO - Dependencies all met for dep_context=non-requeueable deps ti=<TaskInstance: covid_data_dag.download_cases_deaths manual__2023-11-09T10:20:13.629503+00:00 [queued]>
[2023-11-09T10:20:25.369+0000] {taskinstance.py:1157} INFO - Dependencies all met for dep_context=requeueable deps ti=<TaskInstance: covid_data_dag.download_cases_deaths manual__2023-11-09T10:20:13.629503+00:00 [queued]>
[2023-11-09T10:20:25.370+0000] {taskinstance.py:1359} INFO - Starting attempt 1 of 2
[2023-11-09T10:20:25.425+0000] {taskinstance.py:1380} INFO - Executing <Task(PythonOperator): download_cases_deaths> on 2023-11-09 10:20:13.629503+00:00
[2023-11-09T10:20:25.445+0000] {standard_task_runner.py:57} INFO - Started process 1019 to run task
[2023-11-09T10:20:25.468+0000] {standard_task_runner.py:84} INFO - Running: ['***', 'tasks', 'run', 'covid_data_dag', 'download_cases_deaths', 'manual__2023-11-09T10:20:13.629503+00:00', '--job-id', '682', '--raw', '--subdir', 'DAGS_FOLDER/Dag_postgres.py', '--cfg-path', '/tmp/tmp24kx6jah']
[2023-11-09T10:20:25.488+0000] {standard_task_runner.py:85} INFO - Job 682: Subtask download_cases_deaths
[2023-11-09T10:20:25.769+0000] {task_command.py:415} INFO - Running <TaskInstance: covid_data_dag.download_cases_deaths manual__2023-11-09T10:20:13.629503+00:00 [running]> on host 172.21.0.7
[2023-11-09T10:20:26.538+0000] {taskinstance.py:1660} INFO - Exporting env vars: AIRFLOW_CTX_DAG_OWNER='***' AIRFLOW_CTX_DAG_ID='covid_data_dag' AIRFLOW_CTX_TASK_ID='download_cases_deaths' AIRFLOW_CTX_EXECUTION_DATE='2023-11-09T10:20:13.629503+00:00' AIRFLOW_CTX_TRY_NUMBER='1' AIRFLOW_CTX_DAG_RUN_ID='manual__2023-11-09T10:20:13.629503+00:00'
[2023-11-09T10:21:29.755+0000] {taskinstance.py:1935} ERROR - Task failed with exception
Traceback (most recent call last):
  File "/home/airflow/.local/lib/python3.8/site-packages/airflow/operators/python.py", line 192, in execute
    return_value = self.execute_callable()
  File "/home/airflow/.local/lib/python3.8/site-packages/airflow/operators/python.py", line 209, in execute_callable
    return self.python_callable(*self.op_args, **self.op_kwargs)
  File "/opt/airflow/dags/Dag_postgres.py", line 37, in download_cases_deaths
    with open('/opt/airflow/dags/postgres/cases_deaths.csv', 'wb') as f:
FileNotFoundError: [Errno 2] No such file or directory: '/opt/airflow/dags/postgres/cases_deaths.csv'
[2023-11-09T10:21:29.780+0000] {taskinstance.py:1398} INFO - Marking task as UP_FOR_RETRY. dag_id=covid_data_dag, task_id=download_cases_deaths, execution_date=20231109T102013, start_date=20231109T102025, end_date=20231109T102129
[2023-11-09T10:21:29.801+0000] {standard_task_runner.py:104} ERROR - Failed to execute job 682 for task download_cases_deaths ([Errno 2] No such file or directory: '/opt/airflow/dags/postgres/cases_deaths.csv'; 1019)
[2023-11-09T10:21:29.824+0000] {local_task_job_runner.py:228} INFO - Task exited with return code 1
[2023-11-09T10:21:29.863+0000] {taskinstance.py:2776} INFO - 0 downstream tasks scheduled from follow-on schedule check
