[2023-11-14T08:04:24.582+0000] {taskinstance.py:1157} INFO - Dependencies all met for dep_context=non-requeueable deps ti=<TaskInstance: covid_data_dag_postgres.download_cases_deaths manual__2023-11-14T08:04:16.204754+00:00 [queued]>
[2023-11-14T08:04:24.625+0000] {taskinstance.py:1157} INFO - Dependencies all met for dep_context=requeueable deps ti=<TaskInstance: covid_data_dag_postgres.download_cases_deaths manual__2023-11-14T08:04:16.204754+00:00 [queued]>
[2023-11-14T08:04:24.626+0000] {taskinstance.py:1359} INFO - Starting attempt 1 of 2
[2023-11-14T08:04:24.685+0000] {taskinstance.py:1380} INFO - Executing <Task(PythonOperator): download_cases_deaths> on 2023-11-14 08:04:16.204754+00:00
[2023-11-14T08:04:24.723+0000] {standard_task_runner.py:57} INFO - Started process 336 to run task
[2023-11-14T08:04:24.774+0000] {standard_task_runner.py:84} INFO - Running: ['***', 'tasks', 'run', 'covid_data_dag_postgres', 'download_cases_deaths', 'manual__2023-11-14T08:04:16.204754+00:00', '--job-id', '871', '--raw', '--subdir', 'DAGS_FOLDER/Dag_postgres.py', '--cfg-path', '/tmp/tmp4igoyb5w']
[2023-11-14T08:04:24.804+0000] {standard_task_runner.py:85} INFO - Job 871: Subtask download_cases_deaths
[2023-11-14T08:04:26.124+0000] {task_command.py:415} INFO - Running <TaskInstance: covid_data_dag_postgres.download_cases_deaths manual__2023-11-14T08:04:16.204754+00:00 [running]> on host 172.21.0.4
[2023-11-14T08:04:26.705+0000] {taskinstance.py:1660} INFO - Exporting env vars: AIRFLOW_CTX_DAG_OWNER='***' AIRFLOW_CTX_DAG_ID='covid_data_dag_postgres' AIRFLOW_CTX_TASK_ID='download_cases_deaths' AIRFLOW_CTX_EXECUTION_DATE='2023-11-14T08:04:16.204754+00:00' AIRFLOW_CTX_TRY_NUMBER='1' AIRFLOW_CTX_DAG_RUN_ID='manual__2023-11-14T08:04:16.204754+00:00'
[2023-11-14T08:04:32.963+0000] {taskinstance.py:1935} ERROR - Task failed with exception
Traceback (most recent call last):
  File "/home/airflow/.local/lib/python3.8/site-packages/airflow/operators/python.py", line 192, in execute
    return_value = self.execute_callable()
  File "/home/airflow/.local/lib/python3.8/site-packages/airflow/operators/python.py", line 209, in execute_callable
    return self.python_callable(*self.op_args, **self.op_kwargs)
  File "/opt/airflow/dags/Dag_postgres.py", line 38, in download_cases_deaths
    with open('/opt/airflow/dags/postgres/cases_deaths.csv', 'wb') as f:
OSError: [Errno 22] Invalid argument: '/opt/airflow/dags/postgres/cases_deaths.csv'
[2023-11-14T08:04:33.027+0000] {taskinstance.py:1398} INFO - Marking task as UP_FOR_RETRY. dag_id=covid_data_dag_postgres, task_id=download_cases_deaths, execution_date=20231114T080416, start_date=20231114T080424, end_date=20231114T080433
[2023-11-14T08:04:33.078+0000] {standard_task_runner.py:104} ERROR - Failed to execute job 871 for task download_cases_deaths ([Errno 22] Invalid argument: '/opt/airflow/dags/postgres/cases_deaths.csv'; 336)
[2023-11-14T08:04:33.152+0000] {local_task_job_runner.py:228} INFO - Task exited with return code 1
[2023-11-14T08:04:35.580+0000] {taskinstance.py:2776} INFO - 0 downstream tasks scheduled from follow-on schedule check
