[2023-11-19T11:19:47.032+0000] {taskinstance.py:1157} INFO - Dependencies all met for dep_context=non-requeueable deps ti=<TaskInstance: covid_data_dag_postgres_plis.staging.create_vaccinations_table manual__2023-11-19T11:18:56.808445+00:00 [queued]>
[2023-11-19T11:19:47.057+0000] {taskinstance.py:1157} INFO - Dependencies all met for dep_context=requeueable deps ti=<TaskInstance: covid_data_dag_postgres_plis.staging.create_vaccinations_table manual__2023-11-19T11:18:56.808445+00:00 [queued]>
[2023-11-19T11:19:47.058+0000] {taskinstance.py:1359} INFO - Starting attempt 2 of 2
[2023-11-19T11:19:47.112+0000] {taskinstance.py:1380} INFO - Executing <Task(PostgresOperator): staging.create_vaccinations_table> on 2023-11-19 11:18:56.808445+00:00
[2023-11-19T11:19:47.128+0000] {standard_task_runner.py:57} INFO - Started process 1869 to run task
[2023-11-19T11:19:47.146+0000] {standard_task_runner.py:84} INFO - Running: ['***', 'tasks', 'run', 'covid_data_dag_postgres_plis', 'staging.create_vaccinations_table', 'manual__2023-11-19T11:18:56.808445+00:00', '--job-id', '1172', '--raw', '--subdir', 'DAGS_FOLDER/Dag_postgres.py', '--cfg-path', '/tmp/tmpptzjl0ql']
[2023-11-19T11:19:47.152+0000] {standard_task_runner.py:85} INFO - Job 1172: Subtask staging.create_vaccinations_table
[2023-11-19T11:19:48.280+0000] {task_command.py:415} INFO - Running <TaskInstance: covid_data_dag_postgres_plis.staging.create_vaccinations_table manual__2023-11-19T11:18:56.808445+00:00 [running]> on host 172.21.0.3
[2023-11-19T11:19:48.624+0000] {taskinstance.py:1660} INFO - Exporting env vars: AIRFLOW_CTX_DAG_OWNER='***' AIRFLOW_CTX_DAG_ID='covid_data_dag_postgres_plis' AIRFLOW_CTX_TASK_ID='staging.create_vaccinations_table' AIRFLOW_CTX_EXECUTION_DATE='2023-11-19T11:18:56.808445+00:00' AIRFLOW_CTX_TRY_NUMBER='2' AIRFLOW_CTX_DAG_RUN_ID='manual__2023-11-19T11:18:56.808445+00:00'
[2023-11-19T11:19:48.631+0000] {sql.py:274} INFO - Executing: CREATE TABLE vaccinations (
    location VARCHAR,
    iso_code VARCHAR,
    date DATE,
    total_vaccinations INTEGER,
    people_vaccinated INTEGER,
    people_fully_vaccinated INTEGER,
    total_boosters INTEGER,
    daily_vaccinations_raw INTEGER,
    daily_vaccinations INTEGER,
    total_vaccinations_per_hundred DECIMAL,
    people_vaccinated_per_hundred DECIMAL,
    people_fully_vaccinated_per_hundred DECIMAL,
    total_boosters_per_hundred DECIMAL,
    daily_vaccinations_per_million DECIMAL,
    daily_people_vaccinated INTEGER,
    daily_people_vaccinated_per_hundred DECIMAL
);
[2023-11-19T11:19:48.664+0000] {base.py:73} INFO - Using connection ID 'postgres_default' for task execution.
[2023-11-19T11:19:48.717+0000] {base.py:73} INFO - Using connection ID 'postgres_default' for task execution.
[2023-11-19T11:19:48.739+0000] {sql.py:418} INFO - Running statement: CREATE TABLE vaccinations (
    location VARCHAR,
    iso_code VARCHAR,
    date DATE,
    total_vaccinations INTEGER,
    people_vaccinated INTEGER,
    people_fully_vaccinated INTEGER,
    total_boosters INTEGER,
    daily_vaccinations_raw INTEGER,
    daily_vaccinations INTEGER,
    total_vaccinations_per_hundred DECIMAL,
    people_vaccinated_per_hundred DECIMAL,
    people_fully_vaccinated_per_hundred DECIMAL,
    total_boosters_per_hundred DECIMAL,
    daily_vaccinations_per_million DECIMAL,
    daily_people_vaccinated INTEGER,
    daily_people_vaccinated_per_hundred DECIMAL
);, parameters: None
[2023-11-19T11:19:48.742+0000] {taskinstance.py:1935} ERROR - Task failed with exception
Traceback (most recent call last):
  File "/home/airflow/.local/lib/python3.8/site-packages/airflow/providers/common/sql/operators/sql.py", line 280, in execute
    output = hook.run(
  File "/home/airflow/.local/lib/python3.8/site-packages/airflow/providers/common/sql/hooks/sql.py", line 392, in run
    self._run_command(cur, sql_statement, parameters)
  File "/home/airflow/.local/lib/python3.8/site-packages/airflow/providers/common/sql/hooks/sql.py", line 423, in _run_command
    cur.execute(sql_statement)
psycopg2.errors.DuplicateTable: relation "vaccinations" already exists

[2023-11-19T11:19:48.792+0000] {taskinstance.py:1398} INFO - Marking task as FAILED. dag_id=covid_data_dag_postgres_plis, task_id=staging.create_vaccinations_table, execution_date=20231119T111856, start_date=20231119T111947, end_date=20231119T111948
[2023-11-19T11:19:48.898+0000] {standard_task_runner.py:104} ERROR - Failed to execute job 1172 for task staging.create_vaccinations_table (relation "vaccinations" already exists
; 1869)
[2023-11-19T11:19:48.996+0000] {local_task_job_runner.py:228} INFO - Task exited with return code 1
[2023-11-19T11:19:52.699+0000] {taskinstance.py:2776} INFO - 0 downstream tasks scheduled from follow-on schedule check
