[2023-11-08T10:59:49.672+0000] {taskinstance.py:1157} INFO - Dependencies all met for dep_context=non-requeueable deps ti=<TaskInstance: covid_data_dag.store_vaccinations manual__2023-11-08T10:59:26.148555+00:00 [queued]>
[2023-11-08T10:59:49.720+0000] {taskinstance.py:1157} INFO - Dependencies all met for dep_context=requeueable deps ti=<TaskInstance: covid_data_dag.store_vaccinations manual__2023-11-08T10:59:26.148555+00:00 [queued]>
[2023-11-08T10:59:49.727+0000] {taskinstance.py:1359} INFO - Starting attempt 1 of 2
[2023-11-08T10:59:49.800+0000] {taskinstance.py:1380} INFO - Executing <Task(PostgresOperator): store_vaccinations> on 2023-11-08 10:59:26.148555+00:00
[2023-11-08T10:59:49.873+0000] {standard_task_runner.py:57} INFO - Started process 5091 to run task
[2023-11-08T10:59:49.919+0000] {standard_task_runner.py:84} INFO - Running: ['***', 'tasks', 'run', 'covid_data_dag', 'store_vaccinations', 'manual__2023-11-08T10:59:26.148555+00:00', '--job-id', '215', '--raw', '--subdir', 'DAGS_FOLDER/Dag_postgres.py', '--cfg-path', '/tmp/tmpc5zhnqfa']
[2023-11-08T10:59:49.949+0000] {standard_task_runner.py:85} INFO - Job 215: Subtask store_vaccinations
[2023-11-08T10:59:50.209+0000] {task_command.py:415} INFO - Running <TaskInstance: covid_data_dag.store_vaccinations manual__2023-11-08T10:59:26.148555+00:00 [running]> on host 172.21.0.5
[2023-11-08T10:59:50.645+0000] {abstractoperator.py:709} ERROR - Exception rendering Jinja template for task 'store_vaccinations', field 'sql'. Template: 'INSERT INTO vaccinations (iso_code, date, total_vaccinations, people_vaccinated, people_fully_vaccinated, daily_vaccinations_raw, daily_vaccinations, total_vaccinations_per_hundred, people_vaccinated_per_hundred, people_fully_vaccinated_per_hundred, daily_vaccinations_per_million, vaccines, source_name, source_website) SELECT iso_code, date, total_vaccinations, people_vaccinated, people_fully_vaccinated, daily_vaccinations_raw, daily_vaccinations, total_vaccinations_per_hundred, people_vaccinated_per_hundred, people_fully_vaccinated_per_hundred, daily_vaccinations_per_million, vaccines, source_name, source_website FROM csv \'{{"/opt/***/dags/vaccinations.csv"|filename}}\' WITH (FORMAT csv, HEADER true)'
Traceback (most recent call last):
  File "/home/airflow/.local/lib/python3.8/site-packages/airflow/models/abstractoperator.py", line 701, in _do_render_template_fields
    rendered_content = self.render_template(
  File "/home/airflow/.local/lib/python3.8/site-packages/airflow/template/templater.py", line 156, in render_template
    template = jinja_env.from_string(value)
  File "/home/airflow/.local/lib/python3.8/site-packages/jinja2/environment.py", line 1105, in from_string
    return cls.from_code(self, self.compile(source), gs, None)
  File "/home/airflow/.local/lib/python3.8/site-packages/jinja2/environment.py", line 768, in compile
    self.handle_exception(source=source_hint)
  File "/home/airflow/.local/lib/python3.8/site-packages/jinja2/environment.py", line 936, in handle_exception
    raise rewrite_traceback_stack(source=source)
  File "<unknown>", line 1, in template
jinja2.exceptions.TemplateAssertionError: No filter named 'filename'.
[2023-11-08T10:59:50.722+0000] {taskinstance.py:1935} ERROR - Task failed with exception
Traceback (most recent call last):
  File "/home/airflow/.local/lib/python3.8/site-packages/airflow/models/taskinstance.py", line 1516, in _run_raw_task
    self._execute_task_with_callbacks(context, test_mode, session=session)
  File "/home/airflow/.local/lib/python3.8/site-packages/airflow/models/taskinstance.py", line 1645, in _execute_task_with_callbacks
    task_orig = self.render_templates(context=context)
  File "/home/airflow/.local/lib/python3.8/site-packages/airflow/models/taskinstance.py", line 2283, in render_templates
    original_task.render_template_fields(context)
  File "/home/airflow/.local/lib/python3.8/site-packages/airflow/models/baseoperator.py", line 1245, in render_template_fields
    self._do_render_template_fields(self, self.template_fields, context, jinja_env, set())
  File "/home/airflow/.local/lib/python3.8/site-packages/airflow/utils/session.py", line 77, in wrapper
    return func(*args, session=session, **kwargs)
  File "/home/airflow/.local/lib/python3.8/site-packages/airflow/models/abstractoperator.py", line 701, in _do_render_template_fields
    rendered_content = self.render_template(
  File "/home/airflow/.local/lib/python3.8/site-packages/airflow/template/templater.py", line 156, in render_template
    template = jinja_env.from_string(value)
  File "/home/airflow/.local/lib/python3.8/site-packages/jinja2/environment.py", line 1105, in from_string
    return cls.from_code(self, self.compile(source), gs, None)
  File "/home/airflow/.local/lib/python3.8/site-packages/jinja2/environment.py", line 768, in compile
    self.handle_exception(source=source_hint)
  File "/home/airflow/.local/lib/python3.8/site-packages/jinja2/environment.py", line 936, in handle_exception
    raise rewrite_traceback_stack(source=source)
  File "<unknown>", line 1, in template
jinja2.exceptions.TemplateAssertionError: No filter named 'filename'.
[2023-11-08T10:59:50.791+0000] {taskinstance.py:1398} INFO - Marking task as UP_FOR_RETRY. dag_id=covid_data_dag, task_id=store_vaccinations, execution_date=20231108T105926, start_date=20231108T105949, end_date=20231108T105950
[2023-11-08T10:59:50.887+0000] {standard_task_runner.py:104} ERROR - Failed to execute job 215 for task store_vaccinations (No filter named 'filename'.; 5091)
[2023-11-08T10:59:50.927+0000] {local_task_job_runner.py:228} INFO - Task exited with return code 1
[2023-11-08T10:59:51.069+0000] {taskinstance.py:2776} INFO - 0 downstream tasks scheduled from follow-on schedule check
