[2023-11-24T19:02:21.968+0000] {taskinstance.py:1157} INFO - Dependencies all met for dep_context=non-requeueable deps ti=<TaskInstance: covid_data_dag_postgres_plis.staging.pull_cases_deaths manual__2023-11-24T18:57:23.260150+00:00 [queued]>
[2023-11-24T19:02:22.060+0000] {taskinstance.py:1157} INFO - Dependencies all met for dep_context=requeueable deps ti=<TaskInstance: covid_data_dag_postgres_plis.staging.pull_cases_deaths manual__2023-11-24T18:57:23.260150+00:00 [queued]>
[2023-11-24T19:02:22.078+0000] {taskinstance.py:1359} INFO - Starting attempt 1 of 2
[2023-11-24T19:02:22.178+0000] {taskinstance.py:1380} INFO - Executing <Task(PythonOperator): staging.pull_cases_deaths> on 2023-11-24 18:57:23.260150+00:00
[2023-11-24T19:02:22.288+0000] {standard_task_runner.py:57} INFO - Started process 4191 to run task
[2023-11-24T19:02:22.550+0000] {standard_task_runner.py:84} INFO - Running: ['***', 'tasks', 'run', 'covid_data_dag_postgres_plis', 'staging.pull_cases_deaths', 'manual__2023-11-24T18:57:23.260150+00:00', '--job-id', '1486', '--raw', '--subdir', 'DAGS_FOLDER/Dag_postgres.py', '--cfg-path', '/tmp/tmpv0mcebpa']
[2023-11-24T19:02:22.575+0000] {standard_task_runner.py:85} INFO - Job 1486: Subtask staging.pull_cases_deaths
[2023-11-24T19:02:23.696+0000] {task_command.py:415} INFO - Running <TaskInstance: covid_data_dag_postgres_plis.staging.pull_cases_deaths manual__2023-11-24T18:57:23.260150+00:00 [running]> on host 172.21.0.6
[2023-11-24T19:02:25.201+0000] {taskinstance.py:1660} INFO - Exporting env vars: AIRFLOW_CTX_DAG_OWNER='***' AIRFLOW_CTX_DAG_ID='covid_data_dag_postgres_plis' AIRFLOW_CTX_TASK_ID='staging.pull_cases_deaths' AIRFLOW_CTX_EXECUTION_DATE='2023-11-24T18:57:23.260150+00:00' AIRFLOW_CTX_TRY_NUMBER='1' AIRFLOW_CTX_DAG_RUN_ID='manual__2023-11-24T18:57:23.260150+00:00'
[2023-11-24T19:04:39.171+0000] {job.py:219} ERROR - Job heartbeat got an exception
Traceback (most recent call last):
  File "/home/airflow/.local/lib/python3.8/site-packages/sqlalchemy/engine/base.py", line 3371, in _wrap_pool_connect
    return fn()
  File "/home/airflow/.local/lib/python3.8/site-packages/sqlalchemy/pool/base.py", line 327, in connect
    return _ConnectionFairy._checkout(self)
  File "/home/airflow/.local/lib/python3.8/site-packages/sqlalchemy/pool/base.py", line 894, in _checkout
    fairy = _ConnectionRecord.checkout(pool)
  File "/home/airflow/.local/lib/python3.8/site-packages/sqlalchemy/pool/base.py", line 493, in checkout
    rec = pool._do_get()
  File "/home/airflow/.local/lib/python3.8/site-packages/sqlalchemy/pool/impl.py", line 256, in _do_get
    return self._create_connection()
  File "/home/airflow/.local/lib/python3.8/site-packages/sqlalchemy/pool/base.py", line 273, in _create_connection
    return _ConnectionRecord(self)
  File "/home/airflow/.local/lib/python3.8/site-packages/sqlalchemy/pool/base.py", line 388, in __init__
    self.__connect()
  File "/home/airflow/.local/lib/python3.8/site-packages/sqlalchemy/pool/base.py", line 691, in __connect
    pool.logger.debug("Error on connect(): %s", e)
  File "/home/airflow/.local/lib/python3.8/site-packages/sqlalchemy/util/langhelpers.py", line 70, in __exit__
    compat.raise_(
  File "/home/airflow/.local/lib/python3.8/site-packages/sqlalchemy/util/compat.py", line 211, in raise_
    raise exception
  File "/home/airflow/.local/lib/python3.8/site-packages/sqlalchemy/pool/base.py", line 686, in __connect
    self.dbapi_connection = connection = pool._invoke_creator(self)
  File "/home/airflow/.local/lib/python3.8/site-packages/sqlalchemy/engine/create.py", line 574, in connect
    return dialect.connect(*cargs, **cparams)
  File "/home/airflow/.local/lib/python3.8/site-packages/sqlalchemy/engine/default.py", line 598, in connect
    return self.dbapi.connect(*cargs, **cparams)
  File "/home/airflow/.local/lib/python3.8/site-packages/psycopg2/__init__.py", line 122, in connect
    conn = _connect(dsn, connection_factory=connection_factory, **kwasync)
psycopg2.OperationalError: could not translate host name "postgres" to address: Temporary failure in name resolution


The above exception was the direct cause of the following exception:

Traceback (most recent call last):
  File "/home/airflow/.local/lib/python3.8/site-packages/airflow/jobs/job.py", line 190, in heartbeat
    session.merge(self)
  File "/home/airflow/.local/lib/python3.8/site-packages/sqlalchemy/orm/session.py", line 3056, in merge
    return self._merge(
  File "/home/airflow/.local/lib/python3.8/site-packages/sqlalchemy/orm/session.py", line 3136, in _merge
    merged = self.get(
  File "/home/airflow/.local/lib/python3.8/site-packages/sqlalchemy/orm/session.py", line 2853, in get
    return self._get_impl(
  File "/home/airflow/.local/lib/python3.8/site-packages/sqlalchemy/orm/session.py", line 2975, in _get_impl
    return db_load_fn(
  File "/home/airflow/.local/lib/python3.8/site-packages/sqlalchemy/orm/loading.py", line 530, in load_on_pk_identity
    session.execute(
  File "/home/airflow/.local/lib/python3.8/site-packages/sqlalchemy/orm/session.py", line 1716, in execute
    conn = self._connection_for_bind(bind)
  File "/home/airflow/.local/lib/python3.8/site-packages/sqlalchemy/orm/session.py", line 1555, in _connection_for_bind
    return self._transaction._connection_for_bind(
  File "/home/airflow/.local/lib/python3.8/site-packages/sqlalchemy/orm/session.py", line 750, in _connection_for_bind
    conn = bind.connect()
  File "/home/airflow/.local/lib/python3.8/site-packages/sqlalchemy/future/engine.py", line 406, in connect
    return super(Engine, self).connect()
  File "/home/airflow/.local/lib/python3.8/site-packages/sqlalchemy/engine/base.py", line 3325, in connect
    return self._connection_cls(self, close_with_result=close_with_result)
  File "/home/airflow/.local/lib/python3.8/site-packages/sqlalchemy/engine/base.py", line 96, in __init__
    else engine.raw_connection()
  File "/home/airflow/.local/lib/python3.8/site-packages/sqlalchemy/engine/base.py", line 3404, in raw_connection
    return self._wrap_pool_connect(self.pool.connect, _connection)
  File "/home/airflow/.local/lib/python3.8/site-packages/sqlalchemy/engine/base.py", line 3374, in _wrap_pool_connect
    Connection._handle_dbapi_exception_noconnection(
  File "/home/airflow/.local/lib/python3.8/site-packages/sqlalchemy/engine/base.py", line 2208, in _handle_dbapi_exception_noconnection
    util.raise_(
  File "/home/airflow/.local/lib/python3.8/site-packages/sqlalchemy/util/compat.py", line 211, in raise_
    raise exception
  File "/home/airflow/.local/lib/python3.8/site-packages/sqlalchemy/engine/base.py", line 3371, in _wrap_pool_connect
    return fn()
  File "/home/airflow/.local/lib/python3.8/site-packages/sqlalchemy/pool/base.py", line 327, in connect
    return _ConnectionFairy._checkout(self)
  File "/home/airflow/.local/lib/python3.8/site-packages/sqlalchemy/pool/base.py", line 894, in _checkout
    fairy = _ConnectionRecord.checkout(pool)
  File "/home/airflow/.local/lib/python3.8/site-packages/sqlalchemy/pool/base.py", line 493, in checkout
    rec = pool._do_get()
  File "/home/airflow/.local/lib/python3.8/site-packages/sqlalchemy/pool/impl.py", line 256, in _do_get
    return self._create_connection()
  File "/home/airflow/.local/lib/python3.8/site-packages/sqlalchemy/pool/base.py", line 273, in _create_connection
    return _ConnectionRecord(self)
  File "/home/airflow/.local/lib/python3.8/site-packages/sqlalchemy/pool/base.py", line 388, in __init__
    self.__connect()
  File "/home/airflow/.local/lib/python3.8/site-packages/sqlalchemy/pool/base.py", line 691, in __connect
    pool.logger.debug("Error on connect(): %s", e)
  File "/home/airflow/.local/lib/python3.8/site-packages/sqlalchemy/util/langhelpers.py", line 70, in __exit__
    compat.raise_(
  File "/home/airflow/.local/lib/python3.8/site-packages/sqlalchemy/util/compat.py", line 211, in raise_
    raise exception
  File "/home/airflow/.local/lib/python3.8/site-packages/sqlalchemy/pool/base.py", line 686, in __connect
    self.dbapi_connection = connection = pool._invoke_creator(self)
  File "/home/airflow/.local/lib/python3.8/site-packages/sqlalchemy/engine/create.py", line 574, in connect
    return dialect.connect(*cargs, **cparams)
  File "/home/airflow/.local/lib/python3.8/site-packages/sqlalchemy/engine/default.py", line 598, in connect
    return self.dbapi.connect(*cargs, **cparams)
  File "/home/airflow/.local/lib/python3.8/site-packages/psycopg2/__init__.py", line 122, in connect
    conn = _connect(dsn, connection_factory=connection_factory, **kwasync)
sqlalchemy.exc.OperationalError: (psycopg2.OperationalError) could not translate host name "postgres" to address: Temporary failure in name resolution

(Background on this error at: https://sqlalche.me/e/14/e3q8)
[2023-11-24T19:07:58.432+0000] {taskinstance.py:1935} ERROR - Task failed with exception
Traceback (most recent call last):
  File "/home/airflow/.local/lib/python3.8/site-packages/airflow/operators/python.py", line 192, in execute
    return_value = self.execute_callable()
  File "/home/airflow/.local/lib/python3.8/site-packages/airflow/operators/python.py", line 209, in execute_callable
    return self.python_callable(*self.op_args, **self.op_kwargs)
  File "/opt/airflow/dags/Dag_postgres.py", line 168, in _pull_cases_deaths
    data = pd.DataFrame(list(collection.find())).drop('_id', axis=1)
  File "/home/airflow/.local/lib/python3.8/site-packages/pymongo/cursor.py", line 1264, in next
    if len(self.__data) or self._refresh():
  File "/home/airflow/.local/lib/python3.8/site-packages/pymongo/cursor.py", line 1204, in _refresh
    self.__send_message(g)
  File "/home/airflow/.local/lib/python3.8/site-packages/pymongo/cursor.py", line 1060, in __send_message
    response = client._run_operation(
  File "/home/airflow/.local/lib/python3.8/site-packages/pymongo/_csot.py", line 107, in csot_wrapper
    return func(self, *args, **kwargs)
  File "/home/airflow/.local/lib/python3.8/site-packages/pymongo/mongo_client.py", line 1394, in _run_operation
    return self._retryable_read(
  File "/home/airflow/.local/lib/python3.8/site-packages/pymongo/mongo_client.py", line 1492, in _retryable_read
    return self._retry_internal(
  File "/home/airflow/.local/lib/python3.8/site-packages/pymongo/_csot.py", line 107, in csot_wrapper
    return func(self, *args, **kwargs)
  File "/home/airflow/.local/lib/python3.8/site-packages/pymongo/mongo_client.py", line 1453, in _retry_internal
    return _ClientConnectionRetryable(
  File "/home/airflow/.local/lib/python3.8/site-packages/pymongo/mongo_client.py", line 2315, in run
    return self._read() if self._is_read else self._write()
  File "/home/airflow/.local/lib/python3.8/site-packages/pymongo/mongo_client.py", line 2444, in _read
    return self._func(self._session, self._server, conn, read_pref)  # type: ignore
  File "/home/airflow/.local/lib/python3.8/site-packages/pymongo/mongo_client.py", line 1390, in _cmd
    return server.run_operation(
  File "/home/airflow/.local/lib/python3.8/site-packages/pymongo/helpers.py", line 322, in inner
    return func(*args, **kwargs)
  File "/home/airflow/.local/lib/python3.8/site-packages/pymongo/server.py", line 167, in run_operation
    _check_command_response(first, conn.max_wire_version)
  File "/home/airflow/.local/lib/python3.8/site-packages/pymongo/helpers.py", line 228, in _check_command_response
    raise CursorNotFound(errmsg, code, response, max_wire_version)
pymongo.errors.CursorNotFound: cursor id 114170372394599882 not found, full error: {'ok': 0.0, 'errmsg': 'cursor id 114170372394599882 not found', 'code': 43, 'codeName': 'CursorNotFound'}
[2023-11-24T19:07:58.592+0000] {taskinstance.py:1398} INFO - Marking task as UP_FOR_RETRY. dag_id=covid_data_dag_postgres_plis, task_id=staging.pull_cases_deaths, execution_date=20231124T185723, start_date=20231124T190221, end_date=20231124T190758
[2023-11-24T19:07:58.815+0000] {standard_task_runner.py:104} ERROR - Failed to execute job 1486 for task staging.pull_cases_deaths (cursor id 114170372394599882 not found, full error: {'ok': 0.0, 'errmsg': 'cursor id 114170372394599882 not found', 'code': 43, 'codeName': 'CursorNotFound'}; 4191)
[2023-11-24T19:07:59.034+0000] {local_task_job_runner.py:228} INFO - Task exited with return code 1
[2023-11-24T19:08:09.741+0000] {taskinstance.py:2776} INFO - 0 downstream tasks scheduled from follow-on schedule check
