[2023-11-13T16:55:51.435+0000] {taskinstance.py:1157} INFO - Dependencies all met for dep_context=non-requeueable deps ti=<TaskInstance: covid_data_dag_postgres.download_population_data manual__2023-11-13T16:55:17.713971+00:00 [queued]>
[2023-11-13T16:55:51.502+0000] {taskinstance.py:1157} INFO - Dependencies all met for dep_context=requeueable deps ti=<TaskInstance: covid_data_dag_postgres.download_population_data manual__2023-11-13T16:55:17.713971+00:00 [queued]>
[2023-11-13T16:55:51.507+0000] {taskinstance.py:1359} INFO - Starting attempt 2 of 2
[2023-11-13T16:55:51.628+0000] {taskinstance.py:1380} INFO - Executing <Task(PythonOperator): download_population_data> on 2023-11-13 16:55:17.713971+00:00
[2023-11-13T16:55:51.680+0000] {standard_task_runner.py:57} INFO - Started process 866 to run task
[2023-11-13T16:55:51.686+0000] {standard_task_runner.py:84} INFO - Running: ['***', 'tasks', 'run', 'covid_data_dag_postgres', 'download_population_data', 'manual__2023-11-13T16:55:17.713971+00:00', '--job-id', '841', '--raw', '--subdir', 'DAGS_FOLDER/Dag_postgres.py', '--cfg-path', '/tmp/tmplz2ohv_5']
[2023-11-13T16:55:51.732+0000] {standard_task_runner.py:85} INFO - Job 841: Subtask download_population_data
[2023-11-13T16:55:52.686+0000] {task_command.py:415} INFO - Running <TaskInstance: covid_data_dag_postgres.download_population_data manual__2023-11-13T16:55:17.713971+00:00 [running]> on host 172.21.0.9
[2023-11-13T16:55:53.348+0000] {taskinstance.py:1660} INFO - Exporting env vars: AIRFLOW_CTX_DAG_OWNER='***' AIRFLOW_CTX_DAG_ID='covid_data_dag_postgres' AIRFLOW_CTX_TASK_ID='download_population_data' AIRFLOW_CTX_EXECUTION_DATE='2023-11-13T16:55:17.713971+00:00' AIRFLOW_CTX_TRY_NUMBER='2' AIRFLOW_CTX_DAG_RUN_ID='manual__2023-11-13T16:55:17.713971+00:00'
[2023-11-13T16:56:01.523+0000] {taskinstance.py:1935} ERROR - Task failed with exception
Traceback (most recent call last):
  File "/home/airflow/.local/lib/python3.8/site-packages/pandas/core/indexes/base.py", line 3653, in get_loc
    return self._engine.get_loc(casted_key)
  File "pandas/_libs/index.pyx", line 147, in pandas._libs.index.IndexEngine.get_loc
  File "pandas/_libs/index.pyx", line 176, in pandas._libs.index.IndexEngine.get_loc
  File "pandas/_libs/hashtable_class_helper.pxi", line 7080, in pandas._libs.hashtable.PyObjectHashTable.get_item
  File "pandas/_libs/hashtable_class_helper.pxi", line 7088, in pandas._libs.hashtable.PyObjectHashTable.get_item
KeyError: 2022

The above exception was the direct cause of the following exception:

Traceback (most recent call last):
  File "/home/airflow/.local/lib/python3.8/site-packages/airflow/operators/python.py", line 192, in execute
    return_value = self.execute_callable()
  File "/home/airflow/.local/lib/python3.8/site-packages/airflow/operators/python.py", line 209, in execute_callable
    return self.python_callable(*self.op_args, **self.op_kwargs)
  File "/opt/airflow/dags/Dag_postgres.py", line 60, in download_population_data
    data_reshaped[2023] = data_reshaped[2022]
  File "/home/airflow/.local/lib/python3.8/site-packages/pandas/core/frame.py", line 3761, in __getitem__
    indexer = self.columns.get_loc(key)
  File "/home/airflow/.local/lib/python3.8/site-packages/pandas/core/indexes/base.py", line 3655, in get_loc
    raise KeyError(key) from err
KeyError: 2022
[2023-11-13T16:56:01.576+0000] {taskinstance.py:1398} INFO - Marking task as FAILED. dag_id=covid_data_dag_postgres, task_id=download_population_data, execution_date=20231113T165517, start_date=20231113T165551, end_date=20231113T165601
[2023-11-13T16:56:01.627+0000] {standard_task_runner.py:104} ERROR - Failed to execute job 841 for task download_population_data (2022; 866)
[2023-11-13T16:56:01.677+0000] {local_task_job_runner.py:228} INFO - Task exited with return code 1
[2023-11-13T16:56:02.239+0000] {taskinstance.py:2776} INFO - 0 downstream tasks scheduled from follow-on schedule check
